Workbook
Name Months: Lists!$A:$A
Name Years: Lists!$B:$B

Sheet Lists
A1: January | B1: 2022
A2: February | B2: 2023
A3: March | B3: 2024
A4: April | B4: 2025
A5: May | B5: 2026
A6: June | B6: 2027
A7: July
A8: August
A9: September
A10: October
A11: November
A12: December

Sheet Stats
A1: Clinic: | E1: Ben Duke
A2: Month: | B2: January | C2: 2025
A3: New | K3: Totals | P3: OTC Collections
A4: Day of the | B4: Sch | C4: Act | D4: Sch/Act | E4: DAY | F4: % | G4: Pt | H4: % | I4: % | K4: Sch | L4: Act | M4: PV | N4: Charges | O4: Chgs/ | Q4: Pt | R4: Total | S4: Total | T4: Total | V4: Discounts | W4: Total | X4: % | Y4: $PER | Z4: $PER | AA4: VISITS
A5: month | B5: D1 | C5: D1 | D5: D1 | E5: 2 | F5: D1-D2 | G5: Conv | H5: D1-Conv | I5: D2-Conv | J5: Re-Act | K5: PV | L5: PV | M5: % | N5: $$ | O5: Visit | P5: Adjust | Q5: Care | R5: Prod | S5: OTC | T5: PI | U5: Refunds | W5: Coll $ | X5: Coll | Y5: VISIT | Z5: PATIENT | AA5: PATIENT
A6: 1 | P6: =Chiro!N7+Chiro!O7 -> 0 | Q6: =Chiro!P7+Chiro!Q7+TRT!Q6+SDT!Q6+SHP!K6+RLT!K6+EWOT!K6+PEMF!K6+Laser!L6+US!L6+'X-Ray'!O6+Massage!M6 -> 0 | R6: 0 | S6: =Q6+R6+P6 -> 0 | T6: =Chiro!R7 -> 0 | U6: 0 | V6: 0 | W6: =S6+T6-U6-V6 -> 0 | X6: =W6/N6 -> #DIV/0! | Y6: =IFERROR(W6/L6,0) -> 0 | Z6: =IFERROR(W6/G6,0) -> 0 | AA6: =IFERROR(L6/G6,0) -> 0
A7: 2 | B7: 2 | C7: 1 | D7: =IFERROR((C7/B7),0) -> 0.5 | E7: 0 | F7: =E7/C7 -> 0 | G7: 0 | H7: =G7/C7 -> 0 | I7: =G7/E7 -> #DIV/0! | J7: 0 | K7: =Stats!B7+Chiro!H8+TRT!G7+SDT!G7+Laser!G7+US!G7+Massage!E7+'X-Ray'!E7+SHP!G7+RLT!G7+EWOT!G7+PEMF!G7 -> 87 | L7: =Stats!C7+Chiro!I8+TRT!H7+SDT!H7+Laser!H7+US!H7+Massage!F7+'X-Ray'!F7+SHP!H7+RLT!H7+EWOT!H7+PEMF!H7 -> 82 | M7: =IFERROR((L7/K7),0) -> 0.94252874 | N7: 11912.88 | O7: =N7/L7 -> 145.27902 | P7: =Chiro!N8+Chiro!O8 -> 2583.88 | Q7: =Chiro!P8+Chiro!Q8+TRT!Q7+SDT!Q7+SHP!K7+RLT!K7+EWOT!K7+PEMF!K7+Laser!L7+US!L7+'X-Ray'!O7+Massage!M7 -> 2247.5 | R7: 50 | S7: =Q7+R7+P7 -> 4881.38 | T7: =Chiro!R8 -> 0 | U7: 0 | V7: 430 | W7: =S7+T7-U7-V7 -> 4451.38 | X7: =W7/N7 -> 0.37366111 | Y7: =IFERROR(W7/L7,0) -> 54.285122 | Z7: =IFERROR(W7/G7,0) -> 0 | AA7: =IFERROR(L7/G7,0) -> 0
A8: 3 | P8: =Chiro!N9+Chiro!O9 -> 0 | Q8: =Chiro!P9+Chiro!Q9+TRT!Q8+SDT!Q8+SHP!K8+RLT!K8+EWOT!K8+PEMF!K8+Laser!L8+US!L8+'X-Ray'!O8+Massage!M8 -> 1137.5 | R8: 0 | S8: =Q8+R8+P8 -> 1137.5 | T8: =Chiro!R9 -> 0 | U8: 0 | V8: 0 | W8: =S8+T8-U8-V8 -> 1137.5 | X8: =W8/N8 -> #DIV/0! | Y8: =IFERROR(W8/L8,0) -> 0 | Z8: =IFERROR(W8/G8,0) -> 0 | AA8: =IFERROR(L8/G8,0) -> 0
A9: 4 | P9: =Chiro!N10+Chiro!O10 -> 0 | Q9: =Chiro!P10+Chiro!Q10+TRT!Q9+SDT!Q9+SHP!K9+RLT!K9+EWOT!K9+PEMF!K9+Laser!L9+US!L9+'X-Ray'!O9+Massage!M9 -> 400 | R9: 0 | S9: =Q9+R9+P9 -> 400 | T9: =Chiro!R10 -> 0 | U9: 0 | V9: 0 | W9: =S9+T9-U9-V9 -> 400 | X9: =W9/N9 -> #DIV/0! | Y9: =IFERROR(W9/L9,0) -> 0 | Z9: =IFERROR(W9/G9,0) -> 0 | AA9: =IFERROR(L9/G9,0) -> 0
A10: 5 | P10: =Chiro!N11+Chiro!O11 -> 0 | Q10: =Chiro!P11+Chiro!Q11+TRT!Q10+SDT!Q10+SHP!K10+RLT!K10+EWOT!K10+PEMF!K10+Laser!L10+US!L10+'X-Ray'!O10+Massage!M10 -> 400 | R10: 0 | S10: =Q10+R10+P10 -> 400 | T10: =Chiro!R11 -> 0 | U10: 0 | V10: 0 | W10: =S10+T10-U10-V10 -> 400 | X10: =W10/N10 -> #DIV/0! | Y10: =IFERROR(W10/L10,0) -> 0 | Z10: =IFERROR(W10/G10,0) -> 0 | AA10: =IFERROR(L10/G10,0) -> 0
A11: 6 | B11: 0 | C11: 0 | D11: =IFERROR((C11/B11),0) -> 0 | E11: 0 | F11: =E11/C11 -> #DIV/0! | G11: 0 | H11: =G11/C11 -> #DIV/0! | I11: =G11/E11 -> #DIV/0! | J11: 0 | K11: =Stats!B11+Chiro!H12+TRT!G11+SDT!G11+Laser!G11+US!G11+Massage!E11+'X-Ray'!E11+SHP!G11+RLT!G11+EWOT!G11+PEMF!G11 -> 63 | L11: =Stats!C11+Chiro!I12+TRT!H11+SDT!H11+Laser!H11+US!H11+Massage!F11+'X-Ray'!F11+SHP!H11+RLT!H11+EWOT!H11+PEMF!H11 -> 69 | M11: =IFERROR((L11/K11),0) -> 1.0952381 | N11: 13816.68 | O11: =N11/L11 -> 200.24174 | P11: =Chiro!N12+Chiro!O12 -> 2557.44 | Q11: =Chiro!P12+Chiro!Q12+TRT!Q11+SDT!Q11+SHP!K11+RLT!K11+EWOT!K11+PEMF!K11+Laser!L11+US!L11+'X-Ray'!O11+Massage!M11 -> 7603 | R11: 0 | S11: =Q11+R11+P11 -> 10160.44 | T11: =Chiro!R12 -> 0 | U11: 0 | V11: 675 | W11: =S11+T11-U11-V11 -> 9485.44 | X11: =W11/N11 -> 0.68652093 | Y11: =IFERROR(W11/L11,0) -> 137.47014 | Z11: =IFERROR(W11/G11,0) -> 0 | AA11: =IFERROR(L11/G11,0) -> 0
A12: 7 | B12: 2 | C12: 2 | D12: =IFERROR((C12/B12),0) -> 1 | E12: 0 | F12: =E12/C12 -> 0 | G12: 0 | H12: =G12/C12 -> 0 | I12: =G12/E12 -> #DIV/0! | J12: 0 | K12: =Stats!B12+Chiro!H13+TRT!G12+SDT!G12+Laser!G12+US!G12+Massage!E12+'X-Ray'!E12+SHP!G12+RLT!G12+EWOT!G12+PEMF!G12 -> 50 | L12: =Stats!C12+Chiro!I13+TRT!H12+SDT!H12+Laser!H12+US!H12+Massage!F12+'X-Ray'!F12+SHP!H12+RLT!H12+EWOT!H12+PEMF!H12 -> 58 | M12: =IFERROR((L12/K12),0) -> 1.16 | N12: 10481.96 | O12: =N12/L12 -> 180.72345 | P12: =Chiro!N13+Chiro!O13 -> 2232.88 | Q12: =Chiro!P13+Chiro!Q13+TRT!Q12+SDT!Q12+SHP!K12+RLT!K12+EWOT!K12+PEMF!K12+Laser!L12+US!L12+'X-Ray'!O12+Massage!M12 -> 5808 | R12: 0 | S12: =Q12+R12+P12 -> 8040.88 | T12: =Chiro!R13 -> 0 | U12: 0 | V12: 0 | W12: =S12+T12-U12-V12 -> 8040.88 | X12: =W12/N12 -> 0.76711607 | Y12: =IFERROR(W12/L12,0) -> 138.63586 | Z12: =IFERROR(W12/G12,0) -> 0 | AA12: =IFERROR(L12/G12,0) -> 0
A13: 8 | B13: 5 | C13: 5 | D13: =IFERROR((C13/B13),0) -> 1 | E13: 0 | F13: =E13/C13 -> 0 | G13: 0 | H13: =G13/C13 -> 0 | I13: =G13/E13 -> #DIV/0! | J13: 0 | K13: =Stats!B13+Chiro!H14+TRT!G13+SDT!G13+Laser!G13+US!G13+Massage!E13+'X-Ray'!E13+SHP!G13+RLT!G13+EWOT!G13+PEMF!G13 -> 47 | L13: =Stats!C13+Chiro!I14+TRT!H13+SDT!H13+Laser!H13+US!H13+Massage!F13+'X-Ray'!F13+SHP!H13+RLT!H13+EWOT!H13+PEMF!H13 -> 54 | M13: =IFERROR((L13/K13),0) -> 1.1489362 | N13: 8447.48 | O13: =N13/L13 -> 156.43481 | P13: =Chiro!N14+Chiro!O14 -> 2052.48 | Q13: =Chiro!P14+Chiro!Q14+TRT!Q13+SDT!Q13+SHP!K13+RLT!K13+EWOT!K13+PEMF!K13+Laser!L13+US!L13+'X-Ray'!O13+Massage!M13 -> 3074 | R13: 0 | S13: =Q13+R13+P13 -> 5126.48 | T13: =Chiro!R14 -> 0 | U13: 0 | V13: 529 | W13: =S13+T13-U13-V13 -> 4597.48 | X13: =W13/N13 -> 0.54424278 | Y13: =IFERROR(W13/L13,0) -> 85.138519 | Z13: =IFERROR(W13/G13,0) -> 0 | AA13: =IFERROR(L13/G13,0) -> 0
A14: 9 | B14: 1 | C14: 0 | D14: =IFERROR((C14/B14),0) -> 0 | E14: 0 | F14: =E14/C14 -> #DIV/0! | G14: 0 | H14: =G14/C14 -> #DIV/0! | I14: =G14/E14 -> #DIV/0! | J14: 1 | K14: =Stats!B14+Chiro!H15+TRT!G14+SDT!G14+Laser!G14+US!G14+Massage!E14+'X-Ray'!E14+SHP!G14+RLT!G14+EWOT!G14+PEMF!G14 -> 64 | L14: =Stats!C14+Chiro!I15+TRT!H14+SDT!H14+Laser!H14+US!H14+Massage!F14+'X-Ray'!F14+SHP!H14+RLT!H14+EWOT!H14+PEMF!H14 -> 68 | M14: =IFERROR((L14/K14),0) -> 1.0625 | N14: 13253.96 | O14: =N14/L14 -> 194.91118 | P14: =Chiro!N15+Chiro!O15 -> 3232.88 | Q14: =Chiro!P15+Chiro!Q15+TRT!Q14+SDT!Q14+SHP!K14+RLT!K14+EWOT!K14+PEMF!K14+Laser!L14+US!L14+'X-Ray'!O14+Massage!M14 -> 5654 | R14: 50 | S14: =Q14+R14+P14 -> 8936.88 | T14: =Chiro!R15 -> 0 | U14: 0 | V14: 2095 | W14: =S14+T14-U14-V14 -> 6841.88 | X14: =W14/N14 -> 0.51621402 | Y14: =IFERROR(W14/L14,0) -> 100.61588 | Z14: =IFERROR(W14/G14,0) -> 0 | AA14: =IFERROR(L14/G14,0) -> 0
A15: 10 | P15: =Chiro!N16+Chiro!O16 -> 0 | Q15: =Chiro!P16+Chiro!Q16+TRT!Q15+SDT!Q15+SHP!K15+RLT!K15+EWOT!K15+PEMF!K15+Laser!L15+US!L15+'X-Ray'!O15+Massage!M15 -> 400 | R15: 0 | S15: =Q15+R15+P15 -> 400 | T15: =Chiro!R16 -> 0 | U15: 0 | V15: 0 | W15: =S15+T15-U15-V15 -> 400 | X15: =W15/N15 -> #DIV/0! | Y15: =IFERROR(W15/L15,0) -> 0 | Z15: =IFERROR(W15/G15,0) -> 0 | AA15: =IFERROR(L15/G15,0) -> 0
A16: 11 | P16: =Chiro!N17+Chiro!O17 -> 0 | Q16: =Chiro!P17+Chiro!Q17+TRT!Q16+SDT!Q16+SHP!K16+RLT!K16+EWOT!K16+PEMF!K16+Laser!L16+US!L16+'X-Ray'!O16+Massage!M16 -> 0 | R16: 0 | S16: =Q16+R16+P16 -> 0 | T16: =Chiro!R17 -> 0 | U16: 0 | V16: 0 | W16: =S16+T16-U16-V16 -> 0 | X16: =W16/N16 -> #DIV/0! | Y16: =IFERROR(W16/L16,0) -> 0 | Z16: =IFERROR(W16/G16,0) -> 0 | AA16: =IFERROR(L16/G16,0) -> 0
A17: 12 | P17: =Chiro!N18+Chiro!O18 -> 0 | Q17: =Chiro!P18+Chiro!Q18+TRT!Q17+SDT!Q17+SHP!K17+RLT!K17+EWOT!K17+PEMF!K17+Laser!L17+US!L17+'X-Ray'!O17+Massage!M17 -> 0 | R17: 0 | S17: =Q17+R17+P17 -> 0 | T17: =Chiro!R18 -> 0 | U17: 0 | V17: 0 | W17: =S17+T17-U17-V17 -> 0 | X17: =W17/N17 -> #DIV/0! | Y17: =IFERROR(W17/L17,0) -> 0 | Z17: =IFERROR(W17/G17,0) -> 0 | AA17: =IFERROR(L17/G17,0) -> 0
A18: 13 | B18: 1 | C18: 1 | D18: =IFERROR((C18/B18),0) -> 1 | E18: 1 | F18: =E18/C18 -> 1 | G18: 1 | H18: =G18/C18 -> 1 | I18: =G18/E18 -> 1 | J18: 2 | K18: =Stats!B18+Chiro!H19+TRT!G18+SDT!G18+Laser!G18+US!G18+Massage!E18+'X-Ray'!E18+SHP!G18+RLT!G18+EWOT!G18+PEMF!G18 -> 65 | L18: =Stats!C18+Chiro!I19+TRT!H18+SDT!H18+Laser!H18+US!H18+Massage!F18+'X-Ray'!F18+SHP!H18+RLT!H18+EWOT!H18+PEMF!H18 -> 76 | M18: =IFERROR((L18/K18),0) -> 1.1692308 | N18: 12453.68 | O18: =N18/L18 -> 163.86421 | P18: =Chiro!N19+Chiro!O19 -> 1990.36 | Q18: =Chiro!P19+Chiro!Q19+TRT!Q18+SDT!Q18+SHP!K18+RLT!K18+EWOT!K18+PEMF!K18+Laser!L18+US!L18+'X-Ray'!O18+Massage!M18 -> 5260 | R18: 195 | S18: =Q18+R18+P18 -> 7445.36 | T18: =Chiro!R19 -> 0 | U18: 0 | V18: 800 | W18: =S18+T18-U18-V18 -> 6645.36 | X18: =W18/N18 -> 0.53360613 | Y18: =IFERROR(W18/L18,0) -> 87.438947 | Z18: =IFERROR(W18/G18,0) -> 6645.36 | AA18: =IFERROR(L18/G18,0) -> 76
A19: 14 | B19: 0 | C19: 0 | D19: =IFERROR((C19/B19),0) -> 0 | E19: 1 | F19: =E19/C19 -> #DIV/0! | G19: 0 | H19: =G19/C19 -> #DIV/0! | I19: =G19/E19 -> 0 | J19: 0 | K19: =Stats!B19+Chiro!H20+TRT!G19+SDT!G19+Laser!G19+US!G19+Massage!E19+'X-Ray'!E19+SHP!G19+RLT!G19+EWOT!G19+PEMF!G19 -> 45 | L19: =Stats!C19+Chiro!I20+TRT!H19+SDT!H19+Laser!H19+US!H19+Massage!F19+'X-Ray'!F19+SHP!H19+RLT!H19+EWOT!H19+PEMF!H19 -> 55 | M19: =IFERROR((L19/K19),0) -> 1.2222222 | N19: 11511.48 | O19: =N19/L19 -> 209.29964 | P19: =Chiro!N20+Chiro!O20 -> 1452.48 | Q19: =Chiro!P20+Chiro!Q20+TRT!Q19+SDT!Q19+SHP!K19+RLT!K19+EWOT!K19+PEMF!K19+Laser!L19+US!L19+'X-Ray'!O19+Massage!M19 -> 6539 | R19: 0 | S19: =Q19+R19+P19 -> 7991.48 | T19: =Chiro!R20 -> 0 | U19: 0 | V19: 0 | W19: =S19+T19-U19-V19 -> 7991.48 | X19: =W19/N19 -> 0.69421829 | Y19: =IFERROR(W19/L19,0) -> 145.29964 | Z19: =IFERROR(W19/G19,0) -> 0 | AA19: =IFERROR(L19/G19,0) -> 0
A20: 15 | B20: 2 | C20: 2 | D20: =IFERROR((C20/B20),0) -> 1 | E20: 1 | F20: =E20/C20 -> 0.5 | G20: 0 | H20: =G20/C20 -> 0 | I20: =G20/E20 -> 0 | J20: 3 | K20: =Stats!B20+Chiro!H21+TRT!G20+SDT!G20+Laser!G20+US!G20+Massage!E20+'X-Ray'!E20+SHP!G20+RLT!G20+EWOT!G20+PEMF!G20 -> 68 | L20: =Stats!C20+Chiro!I21+TRT!H20+SDT!H20+Laser!H20+US!H20+Massage!F20+'X-Ray'!F20+SHP!H20+RLT!H20+EWOT!H20+PEMF!H20 -> 72 | M20: =IFERROR((L20/K20),0) -> 1.0588235 | N20: 12242.28 | O20: =N20/L20 -> 170.03167 | P20: =Chiro!N21+Chiro!O21 -> 2685.36 | Q20: =Chiro!P21+Chiro!Q21+TRT!Q20+SDT!Q20+SHP!K20+RLT!K20+EWOT!K20+PEMF!K20+Laser!L20+US!L20+'X-Ray'!O20+Massage!M20 -> 5034 | R20: 0 | S20: =Q20+R20+P20 -> 7719.36 | T20: =Chiro!R21 -> 0 | U20: 0 | V20: 635 | W20: =S20+T20-U20-V20 -> 7084.36 | X20: =W20/N20 -> 0.57867979 | Y20: =IFERROR(W20/L20,0) -> 98.393889 | Z20: =IFERROR(W20/G20,0) -> 0 | AA20: =IFERROR(L20/G20,0) -> 0
A21: 16 | B21: 3 | C21: 3 | D21: =IFERROR((C21/B21),0) -> 1 | E21: 1 | F21: =E21/C21 -> 0.33333333 | G21: 1 | H21: =G21/C21 -> 0.33333333 | I21: =G21/E21 -> 1 | J21: 2 | K21: =Stats!B21+Chiro!H22+TRT!G21+SDT!G21+Laser!G21+US!G21+Massage!E21+'X-Ray'!E21+SHP!G21+RLT!G21+EWOT!G21+PEMF!G21 -> 59 | L21: =Stats!C21+Chiro!I22+TRT!H21+SDT!H21+Laser!H21+US!H21+Massage!F21+'X-Ray'!F21+SHP!H21+RLT!H21+EWOT!H21+PEMF!H21 -> 64 | M21: =IFERROR((L21/K21),0) -> 1.0847458 | N21: 14303.36 | O21: =N21/L21 -> 223.49 | P21: =Chiro!N22+Chiro!O22 -> 2533.28 | Q21: =Chiro!P22+Chiro!Q22+TRT!Q21+SDT!Q21+SHP!K21+RLT!K21+EWOT!K21+PEMF!K21+Laser!L21+US!L21+'X-Ray'!O21+Massage!M21 -> 8010 | R21: 1298 | S21: =Q21+R21+P21 -> 11841.28 | T21: =Chiro!R22 -> 1056.48 | U21: 0 | V21: 1565 | W21: =S21+T21-U21-V21 -> 11332.76 | X21: =W21/N21 -> 0.79231453 | Y21: =IFERROR(W21/L21,0) -> 177.07437 | Z21: =IFERROR(W21/G21,0) -> 11332.76 | AA21: =IFERROR(L21/G21,0) -> 64
A22: 17 | P22: =Chiro!N23+Chiro!O23 -> 0 | Q22: =Chiro!P23+Chiro!Q23+TRT!Q22+SDT!Q22+SHP!K22+RLT!K22+EWOT!K22+PEMF!K22+Laser!L22+US!L22+'X-Ray'!O22+Massage!M22 -> 0 | R22: 0 | S22: =Q22+R22+P22 -> 0 | T22: =Chiro!R23 -> 0 | U22: 0 | V22: 0 | W22: =S22+T22-U22-V22 -> 0 | X22: =W22/N22 -> #DIV/0! | Y22: =IFERROR(W22/L22,0) -> 0 | Z22: =IFERROR(W22/G22,0) -> 0 | AA22: =IFERROR(L22/G22,0) -> 0
A23: 18 | P23: =Chiro!N24+Chiro!O24 -> 0 | Q23: =Chiro!P24+Chiro!Q24+TRT!Q23+SDT!Q23+SHP!K23+RLT!K23+EWOT!K23+PEMF!K23+Laser!L23+US!L23+'X-Ray'!O23+Massage!M23 -> 0 | R23: 0 | S23: =Q23+R23+P23 -> 0 | T23: =Chiro!R24 -> 0 | U23: 0 | V23: 0 | W23: =S23+T23-U23-V23 -> 0 | X23: =W23/N23 -> #DIV/0! | Y23: =IFERROR(W23/L23,0) -> 0 | Z23: =IFERROR(W23/G23,0) -> 0 | AA23: =IFERROR(L23/G23,0) -> 0
A24: 19 | P24: =Chiro!N25+Chiro!O25 -> 0 | Q24: =Chiro!P25+Chiro!Q25+TRT!Q24+SDT!Q24+SHP!K24+RLT!K24+EWOT!K24+PEMF!K24+Laser!L24+US!L24+'X-Ray'!O24+Massage!M24 -> 799 | R24: 0 | S24: =Q24+R24+P24 -> 799 | T24: =Chiro!R25 -> 0 | U24: 0 | V24: 0 | W24: =S24+T24-U24-V24 -> 799 | X24: =W24/N24 -> #DIV/0! | Y24: =IFERROR(W24/L24,0) -> 0 | Z24: =IFERROR(W24/G24,0) -> 0 | AA24: =IFERROR(L24/G24,0) -> 0
A25: 20 | B25: 2 | C25: 1 | D25: =IFERROR((C25/B25),0) -> 0.5 | E25: 0 | F25: =E25/C25 -> 0 | G25: 0 | H25: =G25/C25 -> 0 | I25: =G25/E25 -> #DIV/0! | J25: 0 | K25: =Stats!B25+Chiro!H26+TRT!G25+SDT!G25+Laser!G25+US!G25+Massage!E25+'X-Ray'!E25+SHP!G25+RLT!G25+EWOT!G25+PEMF!G25 -> 66 | L25: =Stats!C25+Chiro!I26+TRT!H25+SDT!H25+Laser!H25+US!H25+Massage!F25+'X-Ray'!F25+SHP!H25+RLT!H25+EWOT!H25+PEMF!H25 -> 76 | M25: =IFERROR((L25/K25),0) -> 1.1515152 | N25: 8238.52 | O25: =N25/L25 -> 108.40158 | P25: =Chiro!N26+Chiro!O26 -> 2290.36 | Q25: =Chiro!P26+Chiro!Q26+TRT!Q25+SDT!Q25+SHP!K25+RLT!K25+EWOT!K25+PEMF!K25+Laser!L25+US!L25+'X-Ray'!O25+Massage!M25 -> 1934 | R25: 0 | S25: =Q25+R25+P25 -> 4224.36 | T25: =Chiro!R26 -> 0 | U25: 0 | V25: 250 | W25: =S25+T25-U25-V25 -> 3974.36 | X25: =W25/N25 -> 0.48241189 | Y25: =IFERROR(W25/L25,0) -> 52.294211 | Z25: =IFERROR(W25/G25,0) -> 0 | AA25: =IFERROR(L25/G25,0) -> 0
A26: 21 | B26: 2 | C26: 1 | D26: =IFERROR((C26/B26),0) -> 0.5 | E26: 0 | F26: =E26/C26 -> 0 | G26: 0 | H26: =G26/C26 -> 0 | I26: =G26/E26 -> #DIV/0! | J26: 0 | K26: =Stats!B26+Chiro!H27+TRT!G26+SDT!G26+Laser!G26+US!G26+Massage!E26+'X-Ray'!E26+SHP!G26+RLT!G26+EWOT!G26+PEMF!G26 -> 46 | L26: =Stats!C26+Chiro!I27+TRT!H26+SDT!H26+Laser!H26+US!H26+Massage!F26+'X-Ray'!F26+SHP!H26+RLT!H26+EWOT!H26+PEMF!H26 -> 50 | M26: =IFERROR((L26/K26),0) -> 1.0869565 | N26: 8044.96 | O26: =N26/L26 -> 160.8992 | P26: =Chiro!N27+Chiro!O27 -> 1404.96 | Q26: =Chiro!P27+Chiro!Q27+TRT!Q26+SDT!Q26+SHP!K26+RLT!K26+EWOT!K26+PEMF!K26+Laser!L26+US!L26+'X-Ray'!O26+Massage!M26 -> 3038.33 | R26: 95 | S26: =Q26+R26+P26 -> 4538.29 | T26: =Chiro!R27 -> 0 | U26: 0 | V26: 325 | W26: =S26+T26-U26-V26 -> 4213.29 | X26: =W26/N26 -> 0.52371796 | Y26: =IFERROR(W26/L26,0) -> 84.2658 | Z26: =IFERROR(W26/G26,0) -> 0 | AA26: =IFERROR(L26/G26,0) -> 0
A27: 22 | B27: 0 | C27: 0 | D27: =IFERROR((C27/B27),0) -> 0 | E27: 0 | F27: =E27/C27 -> #DIV/0! | G27: 0 | H27: =G27/C27 -> #DIV/0! | I27: =G27/E27 -> #DIV/0! | J27: 0 | K27: =Stats!B27+Chiro!H28+TRT!G27+SDT!G27+Laser!G27+US!G27+Massage!E27+'X-Ray'!E27+SHP!G27+RLT!G27+EWOT!G27+PEMF!G27 -> 46 | L27: =Stats!C27+Chiro!I28+TRT!H27+SDT!H27+Laser!H27+US!H27+Massage!F27+'X-Ray'!F27+SHP!H27+RLT!H27+EWOT!H27+PEMF!H27 -> 49 | M27: =IFERROR((L27/K27),0) -> 1.0652174 | N27: 13313.64 | O27: =N27/L27 -> 271.70694 | P27: =Chiro!N28+Chiro!O28 -> 1301.64 | Q27: =Chiro!P28+Chiro!Q28+TRT!Q27+SDT!Q27+SHP!K27+RLT!K27+EWOT!K27+PEMF!K27+Laser!L27+US!L27+'X-Ray'!O27+Massage!M27 -> 3670.34 | R27: 1695 | S27: =Q27+R27+P27 -> 6666.98 | T27: =Chiro!R28 -> 0 | U27: 0 | V27: 824 | W27: =S27+T27-U27-V27 -> 5842.98 | X27: =W27/N27 -> 0.43887171 | Y27: =IFERROR(W27/L27,0) -> 119.24449 | Z27: =IFERROR(W27/G27,0) -> 0 | AA27: =IFERROR(L27/G27,0) -> 0
A28: 23 | B28: 0 | C28: 0 | D28: =IFERROR((C28/B28),0) -> 0 | E28: 0 | F28: =E28/C28 -> #DIV/0! | G28: 0 | H28: =G28/C28 -> #DIV/0! | I28: =G28/E28 -> #DIV/0! | J28: 0 | K28: =Stats!B28+Chiro!H29+TRT!G28+SDT!G28+Laser!G28+US!G28+Massage!E28+'X-Ray'!E28+SHP!G28+RLT!G28+EWOT!G28+PEMF!G28 -> 52 | L28: =Stats!C28+Chiro!I29+TRT!H28+SDT!H28+Laser!H28+US!H28+Massage!F28+'X-Ray'!F28+SHP!H28+RLT!H28+EWOT!H28+PEMF!H28 -> 54 | M28: =IFERROR((L28/K28),0) -> 1.0384615 | N28: 12314.24 | O28: =N28/L28 -> 228.04148 | P28: =Chiro!N29+Chiro!O29 -> 1637.8 | Q28: =Chiro!P29+Chiro!Q29+TRT!Q28+SDT!Q28+SHP!K28+RLT!K28+EWOT!K28+PEMF!K28+Laser!L28+US!L28+'X-Ray'!O28+Massage!M28 -> 6880 | R28: 182.2 | S28: =Q28+R28+P28 -> 8700 | T28: =Chiro!R29 -> 0 | U28: 0 | V28: 775 | W28: =S28+T28-U28-V28 -> 7925 | X28: =W28/N28 -> 0.64356387 | Y28: =IFERROR(W28/L28,0) -> 146.75926 | Z28: =IFERROR(W28/G28,0) -> 0 | AA28: =IFERROR(L28/G28,0) -> 0
A29: 24 | P29: =Chiro!N30+Chiro!O30 -> 0 | Q29: =Chiro!P30+Chiro!Q30+TRT!Q29+SDT!Q29+SHP!K29+RLT!K29+EWOT!K29+PEMF!K29+Laser!L29+US!L29+'X-Ray'!O29+Massage!M29 -> 200 | R29: 0 | S29: =Q29+R29+P29 -> 200 | T29: =Chiro!R30 -> 0 | U29: 0 | V29: 0 | W29: =S29+T29-U29-V29 -> 200 | X29: =W29/N29 -> #DIV/0! | Y29: =IFERROR(W29/L29,0) -> 0 | Z29: =IFERROR(W29/G29,0) -> 0 | AA29: =IFERROR(L29/G29,0) -> 0
A30: 25 | P30: =Chiro!N31+Chiro!O31 -> 0 | Q30: =Chiro!P31+Chiro!Q31+TRT!Q30+SDT!Q30+SHP!K30+RLT!K30+EWOT!K30+PEMF!K30+Laser!L30+US!L30+'X-Ray'!O30+Massage!M30 -> 700 | R30: 0 | S30: =Q30+R30+P30 -> 700 | T30: =Chiro!R31 -> 0 | U30: 0 | V30: 0 | W30: =S30+T30-U30-V30 -> 700 | X30: =W30/N30 -> #DIV/0! | Y30: =IFERROR(W30/L30,0) -> 0 | Z30: =IFERROR(W30/G30,0) -> 0 | AA30: =IFERROR(L30/G30,0) -> 0
A31: 26 | P31: =Chiro!N32+Chiro!O32 -> 0 | Q31: =Chiro!P32+Chiro!Q32+TRT!Q31+SDT!Q31+SHP!K31+RLT!K31+EWOT!K31+PEMF!K31+Laser!L31+US!L31+'X-Ray'!O31+Massage!M31 -> 0 | R31: 0 | S31: =Q31+R31+P31 -> 0 | T31: =Chiro!R32 -> 0 | U31: 0 | V31: 0 | W31: =S31+T31-U31-V31 -> 0 | X31: =W31/N31 -> #DIV/0! | Y31: =IFERROR(W31/L31,0) -> 0 | Z31: =IFERROR(W31/G31,0) -> 0 | AA31: =IFERROR(L31/G31,0) -> 0
A32: 27 | B32: 1 | C32: 1 | D32: =IFERROR((C32/B32),0) -> 1 | E32: 0 | F32: =E32/C32 -> 0 | G32: 0 | H32: =G32/C32 -> 0 | I32: =G32/E32 -> #DIV/0! | J32: 0 | K32: =Stats!B32+Chiro!H33+TRT!G32+SDT!G32+Laser!G32+US!G32+Massage!E32+'X-Ray'!E32+SHP!G32+RLT!G32+EWOT!G32+PEMF!G32 -> 72 | L32: =Stats!C32+Chiro!I33+TRT!H32+SDT!H32+Laser!H32+US!H32+Massage!F32+'X-Ray'!F32+SHP!H32+RLT!H32+EWOT!H32+PEMF!H32 -> 71 | M32: =IFERROR((L32/K32),0) -> 0.98611111 | N32: 9596.44 | O32: =N32/L32 -> 135.16113 | P32: =Chiro!N33+Chiro!O33 -> 2290.36 | Q32: =Chiro!P33+Chiro!Q33+TRT!Q32+SDT!Q32+SHP!K32+RLT!K32+EWOT!K32+PEMF!K32+Laser!L32+US!L32+'X-Ray'!O32+Massage!M32 -> 3294 | R32: 0 | S32: =Q32+R32+P32 -> 5584.36 | T32: =Chiro!R33 -> 0 | U32: 0 | V32: 142.08 | W32: =S32+T32-U32-V32 -> 5442.28 | X32: =W32/N32 -> 0.56711447 | Y32: =IFERROR(W32/L32,0) -> 76.651831 | Z32: =IFERROR(W32/G32,0) -> 0 | AA32: =IFERROR(L32/G32,0) -> 0
A33: 28 | B33: 0 | C33: 0 | D33: =IFERROR((C33/B33),0) -> 0 | E33: 0 | F33: =E33/C33 -> #DIV/0! | G33: 0 | H33: =G33/C33 -> #DIV/0! | I33: =G33/E33 -> #DIV/0! | J33: 1 | K33: =Stats!B33+Chiro!H34+TRT!G33+SDT!G33+Laser!G33+US!G33+Massage!E33+'X-Ray'!E33+SHP!G33+RLT!G33+EWOT!G33+PEMF!G33 -> 44 | L33: =Stats!C33+Chiro!I34+TRT!H33+SDT!H33+Laser!H33+US!H33+Massage!F33+'X-Ray'!F33+SHP!H33+RLT!H33+EWOT!H33+PEMF!H33 -> 49 | M33: =IFERROR((L33/K33),0) -> 1.1136364 | N33: 6759.4 | O33: =N33/L33 -> 137.94694 | P33: =Chiro!N34+Chiro!O34 -> 1695.4 | Q33: =Chiro!P34+Chiro!Q34+TRT!Q33+SDT!Q33+SHP!K33+RLT!K33+EWOT!K33+PEMF!K33+Laser!L33+US!L33+'X-Ray'!O33+Massage!M33 -> 2414 | R33: 0 | S33: =Q33+R33+P33 -> 4109.4 | T33: =Chiro!R34 -> 0 | U33: 0 | V33: 505 | W33: =S33+T33-U33-V33 -> 3604.4 | X33: =W33/N33 -> 0.5332426 | Y33: =IFERROR(W33/L33,0) -> 73.559184 | Z33: =IFERROR(W33/G33,0) -> 0 | AA33: =IFERROR(L33/G33,0) -> 0
A34: 29 | B34: 0 | C34: 0 | D34: =IFERROR((C34/B34),0) -> 0 | E34: 0 | F34: =E34/C34 -> #DIV/0! | G34: 0 | H34: =G34/C34 -> #DIV/0! | I34: =G34/E34 -> #DIV/0! | J34: 0 | K34: =Stats!B34+Chiro!H35+TRT!G34+SDT!G34+Laser!G34+US!G34+Massage!E34+'X-Ray'!E34+SHP!G34+RLT!G34+EWOT!G34+PEMF!G34 -> 56 | L34: =Stats!C34+Chiro!I35+TRT!H34+SDT!H34+Laser!H34+US!H34+Massage!F34+'X-Ray'!F34+SHP!H34+RLT!H34+EWOT!H34+PEMF!H34 -> 58 | M34: =IFERROR((L34/K34),0) -> 1.0357143 | N34: 9547.04 | O34: =N34/L34 -> 164.60414 | P34: =Chiro!N35+Chiro!O35 -> 1805.96 | Q34: =Chiro!P35+Chiro!Q35+TRT!Q34+SDT!Q34+SHP!K34+RLT!K34+EWOT!K34+PEMF!K34+Laser!L34+US!L34+'X-Ray'!O34+Massage!M34 -> 1341.67 | R34: 0 | S34: =Q34+R34+P34 -> 3147.63 | T34: =Chiro!R35 -> 0 | U34: 0 | V34: 0 | W34: =S34+T34-U34-V34 -> 3147.63 | X34: =W34/N34 -> 0.32969695 | Y34: =IFERROR(W34/L34,0) -> 54.269483 | Z34: =IFERROR(W34/G34,0) -> 0 | AA34: =IFERROR(L34/G34,0) -> 0
A35: 30 | B35: 0 | C35: 0 | D35: =IFERROR((C35/B35),0) -> 0 | E35: 0 | F35: =E35/C35 -> #DIV/0! | G35: 0 | H35: =G35/C35 -> #DIV/0! | I35: =G35/E35 -> #DIV/0! | J35: 1 | K35: =Stats!B35+Chiro!H36+TRT!G35+SDT!G35+Laser!G35+US!G35+Massage!E35+'X-Ray'!E35+SHP!G35+RLT!G35+EWOT!G35+PEMF!G35 -> 50 | L35: =Stats!C35+Chiro!I36+TRT!H35+SDT!H35+Laser!H35+US!H35+Massage!F35+'X-Ray'!F35+SHP!H35+RLT!H35+EWOT!H35+PEMF!H35 -> 59 | M35: =IFERROR((L35/K35),0) -> 1.18 | N35: 12560.2 | O35: =N35/L35 -> 212.88475 | P35: =Chiro!N36+Chiro!O36 -> 1679.12 | Q35: =Chiro!P36+Chiro!Q36+TRT!Q35+SDT!Q35+SHP!K35+RLT!K35+EWOT!K35+PEMF!K35+Laser!L35+US!L35+'X-Ray'!O35+Massage!M35 -> 6814.5 | R35: 600 | S35: =Q35+R35+P35 -> 9093.62 | T35: =Chiro!R36 -> 0 | U35: 200 | V35: 2193 | W35: =S35+T35-U35-V35 -> 6700.62 | X35: =W35/N35 -> 0.53348036 | Y35: =IFERROR(W35/L35,0) -> 113.56983 | Z35: =IFERROR(W35/G35,0) -> 0 | AA35: =IFERROR(L35/G35,0) -> 0
A36: 31 | P36: =Chiro!N37+Chiro!O37 -> 0 | Q36: =Chiro!P37+Chiro!Q37+TRT!Q36+SDT!Q36+SHP!K36+RLT!K36+EWOT!K36+PEMF!K36+Laser!L36+US!L36+'X-Ray'!O36+Massage!M36 -> 200 | R36: 0 | S36: =Q36+R36+P36 -> 200 | T36: =Chiro!R37 -> 0 | U36: 0 | V36: 0 | W36: =S36+T36-U36-V36 -> 200 | X36: =W36/N36 -> #DIV/0! | Y36: =IFERROR(W36/L36,0) -> 0 | Z36: =IFERROR(W36/G36,0) -> 0 | AA36: =IFERROR(L36/G36,0) -> 0
A37: Total | B37: =SUM(B6:B36) -> 21 | C37: =SUM(C6:C36) -> 17 | D37: =IFERROR((C37/B37),0) -> 0.80952381 | E37: =SUM(E6:E36) -> 4 | F37: =E37/C37 -> 0.23529412 | G37: =SUM(G6:G36) -> 2 | H37: =G37/C37 -> 0.11764706 | I37: =G37/E37 -> 0.5 | J37: =SUM(J6:J36) -> 10 | K37: =SUM(K6:K36) -> 980 | L37: =SUM(L6:L36) -> 1064 | M37: =IFERROR((L37/K37),0) -> 1.0857143 | N37: =SUM(N6:N36) -> 188798.2 | O37: =N37/L37 -> 177.44192 | P37: =SUM(P6:P36) -> 35426.64 | Q37: =SUM(Q6:Q36) -> 82852.84 | R37: =SUM(R6:R36) -> 4165.2 | S37: =SUM(S6:S36) -> 122444.68 | T37: =SUM(T6:T36) -> 1056.48 | U37: =SUM(U6:U36) -> 200 | V37: =SUM(V6:V36) -> 11743.08 | W37: =SUM(W6:W36) -> 111558.08 | X37: =W37/N37 -> 0.59088529 | Y37: =SUM(Y6:Y36) -> 1744.9665 | Z37: =SUM(Z6:Z36) -> 17978.12 | AA37: =SUM(AA6:AA36) -> 140
A38: Daily Avg | B38: =B37/$B$39 -> 1.2352941 | C38: =C37/$B$39 -> 1 | D38: =IFERROR((C38/B38),0) -> 0.80952381 | E38: =E37/$B$39 -> 0.23529412 | F38: =E38/C38 -> 0.23529412 | G38: =G37/B39 -> 0.11764706 | H38: =H37/B39 -> 0.0069204152 | I38: =I37/B39 -> 0.029411765 | J38: =J37/B39 -> 0.58823529 | K38: =K37/$B$39 -> 57.647059 | L38: =L37/$B$39 -> 62.588235 | M38: =IFERROR((L38/K38),0) -> 1.0857143 | N38: =N37/$B$39 -> 11105.776 | O38: =N38/L38 -> 177.44192 | P38: =P37/$B$39 -> 2083.92 | Q38: =Q37/$B$39 -> 4873.6965 | R38: =R37/$B$39 -> 245.01176 | S38: =S37/$B$39 -> 7202.6282 | T38: =T37/$B$39 -> 62.145882 | U38: =U37/$B$39 -> 11.764706 | V38: =V37/$B$39 -> 690.76941 | W38: =W37/$B$39 -> 6562.24 | X38: =W38/N38 -> 0.59088529 | Y38: =Y37/$B$39 -> 102.64509 | Z38: =Z37/$B$39 -> 1057.5365 | AA38: =AA37/$B$39 -> 8.2352941
A39: DOM | B39: 17

Sheet Chiro
A1: Clinic:
A2: Month: | B2: =Stats!B2 -> January | C2: =Stats!C2 -> 2025
A3: Visits | H3: Totals | L3: Charges | N3: Collections
A4: Patient Visits | N4: Cash & Medicare | R4: PIP
A5: Day of the | B5: Sch | C5: Act | D5: Sch | E5: Act | F5: Sch | G5: Act | H5: Sch | I5: Act | J5: PV | K5: Total | L5: Total | M5: Total | N5: M/C | O5: Cash | P5: Both | Q5: Chiro | R5: Total
A6: month | B6: Adj | C6: Adj | D6: PIP | E6: PIP | F6: Cons. | G6: Cons. | H6: PV | I6: PV | J6: % | K6: ADJ | L6: Adj | M6: Consult | N6: Adj | O6: Adj | P6: Consult | Q6: Pkgs | R6: $
A7: 1
A8: 2 | B8: 50 | C8: 52 | D8: 0 | E8: 0 | F8: 4 | G8: 2 | H8: =B8+D8+F8 -> 54 | I8: =C8+E8+G8 -> 54 | J8: =I8/H8 -> 1 | K8: 62 | L8: 4012.88 | M8: 325 | N8: 462.88 | O8: 2121 | P8: 110 | Q8: 0 | R8: 0
A9: 3 | Q9: 700
A10: 4 | Q10: 400
A11: 5 | Q11: 400
A12: 6 | B12: 30 | C12: 37 | D12: 1 | E12: 1 | F12: 2 | G12: 3 | H12: =B12+D12+F12 -> 33 | I12: =C12+E12+G12 -> 41 | J12: =I12/H12 -> 1.2424242 | K12: 52 | L12: 3303.68 | M12: 415 | N12: 757.44 | O12: 1800 | P12: 265 | Q12: 2800 | R12: 0
A13: 7 | B13: 30 | C13: 37 | D13: 0 | E13: 0 | F13: 0 | G13: 0 | H13: =B13+D13+F13 -> 30 | I13: =C13+E13+G13 -> 37 | J13: =I13/H13 -> 1.2333333 | K13: 44 | L13: 2874.96 | M13: 360 | N13: 504.96 | O13: 1727.92 | P13: 360 | Q13: 900 | R13: 0
A14: 8 | B14: 25 | C14: 32 | D14: 0 | E14: 0 | F14: 0 | G14: 0 | H14: =B14+D14+F14 -> 25 | I14: =C14+E14+G14 -> 32 | J14: =I14/H14 -> 1.28 | K14: 40 | L14: 2827.48 | M14: 1050 | N14: 252.48 | O14: 1800 | P14: 720 | Q14: 1400 | R14: 0
A15: 9 | B15: 28 | C15: 34 | D15: 1 | E15: 0 | F15: 1 | G15: 1 | H15: =B15+D15+F15 -> 30 | I15: =C15+E15+G15 -> 35 | J15: =I15/H15 -> 1.1666667 | K15: 45 | L15: 2979.96 | M15: 65 | N15: 462.88 | O15: 2770 | P15: 65 | Q15: 1400 | R15: 0
A16: 10 | Q16: 400
A17: 11
A18: 12
A19: 13 | B19: 31 | C19: 42 | D19: 0 | E19: 0 | F19: 2 | G19: 3 | H19: =B19+D19+F19 -> 33 | I19: =C19+E19+G19 -> 45 | J19: =I19/H19 -> 1.3636364 | K19: 54 | L19: 3358.68 | M19: 375 | N19: 715.36 | O19: 1275 | P19: 310 | Q19: 2250 | R19: 0
A20: 14 | B20: 26 | C20: 34 | D20: 0 | E20: 0 | F20: 2 | G20: 2 | H20: =B20+D20+F20 -> 28 | I20: =C20+E20+G20 -> 36 | J20: =I20/H20 -> 1.2857143 | K20: 42 | L20: 2892.48 | M20: 0 | N20: 210.4 | O20: 1242.08 | P20: 0 | Q20: 5740 | R20: 0
A21: 15 | B21: 34 | C21: 40 | D21: 1 | E21: 1 | F21: 4 | G21: 4 | H21: =B21+D21+F21 -> 39 | I21: =C21+E21+G21 -> 45 | J21: =I21/H21 -> 1.1538462 | K21: 50 | L21: 3298.28 | M21: 920 | N21: 757.44 | O21: 1927.92 | P21: 555 | Q21: 1800 | R21: 0
A22: 16 | B22: 32 | C22: 36 | D22: 0 | E22: 0 | F22: 2 | G22: 3 | H22: =B22+D22+F22 -> 34 | I22: =C22+E22+G22 -> 39 | J22: =I22/H22 -> 1.1470588 | K22: 49 | L22: 3115.36 | M22: 735 | N22: 631.2 | O22: 1902.08 | P22: 735 | Q22: 1100 | R22: 1056.48
A23: 17
A24: 18
A25: 19 | Q25: 200
A26: 20 | B26: 36 | C26: 49 | D26: 1 | E26: 1 | F26: 0 | G26: 0 | H26: =B26+D26+F26 -> 37 | I26: =C26+E26+G26 -> 50 | J26: =I26/H26 -> 1.3513514 | K26: 59 | L26: 3824.52 | M26: 395 | N26: 716.28 | O26: 1574.08 | P26: 180 | Q26: 0 | R26: 0
A27: 21 | B27: 25 | C27: 29 | D27: 0 | E27: 0 | F27: 3 | G27: 3 | H27: =B27+D27+F27 -> 28 | I27: =C27+E27+G27 -> 32 | J27: =I27/H27 -> 1.1428571 | K27: 34 | L27: 2154.96 | M27: 445 | N27: 504.96 | O27: 900 | P27: 230 | Q27: 925 | R27: 0
A28: 22 | B28: 26 | C28: 28 | D28: 1 | E28: 1 | F28: 0 | G28: 0 | H28: =B28+D28+F28 -> 27 | I28: =C28+E28+G28 -> 29 | J28: =I28/H28 -> 1.0740741 | K28: 35 | L28: 2436.64 | M28: 300 | N28: 336.64 | O28: 965 | P28: 150 | Q28: 0 | R28: 0
A29: 23 | B29: 28 | C29: 32 | D29: 0 | E29: 0 | F29: 0 | G29: 0 | H29: =B29+D29+F29 -> 28 | I29: =C29+E29+G29 -> 32 | J29: =I29/H29 -> 1.1428571 | K29: 41 | L29: 2617.04 | M29: 0 | N29: 462.88 | O29: 1174.92 | P29: 0 | Q29: 3250 | R29: 0
A30: 24 | Q30: 200
A31: 25 | Q31: 700
A32: 26
A33: 27 | B33: 43 | C33: 45 | D33: 1 | E33: 1 | F33: 1 | G33: 1 | H33: =B33+D33+F33 -> 45 | I33: =C33+E33+G33 -> 47 | J33: =I33/H33 -> 1.0444444 | K33: 55 | L33: 3557.44 | M33: 380 | N33: 673.28 | O33: 1617.08 | P33: 230 | Q33: 0 | R33: 0
A34: 28 | B34: 31 | C34: 34 | D34: 0 | E34: 0 | F34: 1 | G34: 1 | H34: =B34+D34+F34 -> 32 | I34: =C34+E34+G34 -> 35 | J34: =I34/H34 -> 1.09375 | K34: 41 | L34: 2820.4 | M34: 65 | N34: 210.4 | O34: 1485 | P34: 65 | Q34: 0 | R34: 0
A35: 29 | B35: 33 | C35: 37 | D35: 1 | E35: 1 | F35: 1 | G35: 0 | H35: =B35+D35+F35 -> 35 | I35: =C35+E35+G35 -> 38 | J35: =I35/H35 -> 1.0857143 | K35: 43 | L35: 2847.04 | M35: 150 | N35: 462.88 | O35: 1343.08 | P35: 0 | Q35: 200 | R35: 0
A36: 30 | B36: 24 | C36: 32 | D36: 0 | E36: 0 | F36: 0 | G36: 1 | H36: =B36+D36+F36 -> 24 | I36: =C36+E36+G36 -> 33 | J36: =I36/H36 -> 1.375 | K36: 41 | L36: 2606.2 | M36: 65 | N36: 589.12 | O36: 1090 | P36: 65 | Q36: 750 | R36: 0
A37: 31 | Q37: 200
A38: Total | B38: =SUM(B7:B37) -> 532 | C38: =SUM(C7:C37) -> 630 | D38: =SUM(D7:D37) -> 7 | E38: =SUM(E7:E37) -> 6 | F38: =SUM(F7:F37) -> 23 | G38: =SUM(G7:G37) -> 24 | H38: =SUM(H7:H37) -> 562 | I38: =SUM(I7:I37) -> 660 | K38: =SUM(K7:K37) -> 787 | L38: =SUM(L7:L37) -> 51528 | M38: =SUM(M7:M37) -> 6045 | N38: =SUM(N7:N37) -> 8711.48 | O38: =SUM(O7:O37) -> 26715.16 | P38: =SUM(P7:P37) -> 4040 | Q38: =SUM(Q7:Q37) -> 25715 | R38: =SUM(R7:R37) -> 1056.48
A39: Daily Avg | B39: =AVERAGE(B7:B37) -> 31.294118 | C39: =AVERAGE(C7:C37) -> 37.058824 | D39: =AVERAGE(D7:D37) -> 0.41176471 | E39: =AVERAGE(E7:E37) -> 0.35294118 | F39: =AVERAGE(F7:F37) -> 1.3529412 | G39: =AVERAGE(G7:G37) -> 1.4117647 | H39: =AVERAGE(H7:H37) -> 33.058824 | I39: =AVERAGE(I7:I37) -> 38.823529 | K39: =K38/B40 -> 46.294118 | L39: =AVERAGE(L7:L37) -> 3031.0588 | M39: =AVERAGE(M7:M37) -> 355.58824 | N39: =AVERAGE(N7:N37) -> 512.44 | O39: =AVERAGE(O7:O37) -> 1571.48 | P39: =AVERAGE(P7:P37) -> 237.64706 | R39: =AVERAGE(R7:R37) -> 62.145882
A40: DOM | B40: =Stats!B39 -> 17
...

Sheet Massage
A1: Clinic:
A2: Month: | B2: =Stats!B2 -> January | C2: =Stats!C2 -> 2025
A3: New | E3: Totals
A4: Day of the | B4: Sch | C4: Act | D4: Sch/Act | E4: Sch | F4: Act | G4: PV | H4: 30 | I4: 45 | J4: 60 | K4: 75 | L4: 90
A5: month | B5: D1 | C5: D1 | D5: D1 | E5: PV | F5: PV | G5: % | H5: min | I5: min | J5: min | K5: min | L5: min | M5: Total $
A6: 1
A7: 2 | B7: 0 | C7: 0 | D7: =IFERROR((C7/B7),0) -> 0 | E7: 6 | F7: =H7+I7+J7+K7+L7 -> 5 | G7: =IFERROR((F7/E7),0) -> 0.83333333 | H7: 0 | I7: 0 | J7: 3 | K7: 0 | L7: 2 | M7: 350
A8: 3
A9: 4
A10: 5
A11: 6 | B11: 0 | C11: 0 | D11: =IFERROR((C11/B11),0) -> 0 | E11: 5 | F11: =H11+I11+J11+K11+L11 -> 4 | G11: =IFERROR((F11/E11),0) -> 0.8 | H11: 0 | I11: 0 | J11: 3 | K11: 0 | L11: 1 | M11: 520
A12: 7 | B12: 0 | C12: 0 | D12: =IFERROR((C12/B12),0) -> 0 | E12: 6 | F12: =H12+I12+J12+K12+L12 -> 6 | G12: =IFERROR((F12/E12),0) -> 1 | H12: 0 | I12: 1 | J12: 4 | K12: 0 | L12: 1 | M12: 450
A13: 8 | B13: 0 | C13: 0 | D13: =IFERROR((C13/B13),0) -> 0 | E13: 4 | F13: =H13+I13+J13+K13+L13 -> 4 | G13: =IFERROR((F13/E13),0) -> 1 | H13: 0 | I13: 1 | J13: 1 | K13: 0 | L13: 2 | M13: 360
A14: 9 | B14: 0 | C14: 0 | D14: =IFERROR((C14/B14),0) -> 0 | E14: 6 | F14: =H14+I14+J14+K14+L14 -> 5 | G14: =IFERROR((F14/E14),0) -> 0.83333333 | H14: 0 | I14: 2 | J14: 3 | K14: 0 | L14: 0 | M14: 420
A15: 10
A16: 11
A17: 12
A18: 13 | B18: 0 | C18: 0 | D18: =IFERROR((C18/B18),0) -> 0 | E18: 6 | F18: =H18+I18+J18+K18+L18 -> 6 | G18: =IFERROR((F18/E18),0) -> 1 | H18: 0 | I18: 0 | J18: 5 | K18: 0 | L18: 1 | M18: 240
A19: 14 | B19: 0 | C19: 0 | D19: =IFERROR((C19/B19),0) -> 0 | E19: 4 | F19: =H19+I19+J19+K19+L19 -> 4 | G19: =IFERROR((F19/E19),0) -> 1 | H19: 0 | I19: 0 | J19: 2 | K19: 0 | L19: 2 | M19: 480
A20: 15 | B20: 0 | C20: 0 | D20: =IFERROR((C20/B20),0) -> 0 | E20: 6 | F20: =H20+I20+J20+K20+L20 -> 6 | G20: =IFERROR((F20/E20),0) -> 1 | H20: 0 | I20: 1 | J20: 4 | K20: 0 | L20: 1 | M20: 1660
A21: 16 | B21: 0 | C21: 0 | D21: =IFERROR((C21/B21),0) -> 0 | E21: 6 | F21: =H21+I21+J21+K21+L21 -> 5 | G21: =IFERROR((F21/E21),0) -> 0.83333333 | H21: 0 | I21: 0 | J21: 3 | K21: 0 | L21: 2 | M21: 240
A22: 17
A23: 18
A24: 19
A25: 20 | B25: 0 | C25: 0 | D25: =IFERROR((C25/B25),0) -> 0 | E25: 6 | F25: =H25+I25+J25+K25+L25 -> 6 | G25: =IFERROR((F25/E25),0) -> 1 | H25: 0 | I25: 1 | J25: 4 | K25: 0 | L25: 1 | M25: 330
A26: 21 | B26: 0 | C26: 0 | D26: =IFERROR((C26/B26),0) -> 0 | E26: 5 | F26: =H26+I26+J26+K26+L26 -> 5 | G26: =IFERROR((F26/E26),0) -> 1 | H26: 0 | I26: 0 | J26: 3 | K26: 0 | L26: 2 | M26: 300
A27: 22 | B27: 0 | C27: 0 | D27: =IFERROR((C27/B27),0) -> 0 | E27: 6 | F27: =H27+I27+J27+K27+L27 -> 6 | G27: =IFERROR((F27/E27),0) -> 1 | H27: 1 | I27: 1 | J27: 2 | K27: 0 | L27: 2 | M27: 660
A28: 23 | B28: 0 | C28: 0 | D28: =IFERROR((C28/B28),0) -> 0 | E28: 6 | F28: =H28+I28+J28+K28+L28 -> 6 | G28: =IFERROR((F28/E28),0) -> 1 | H28: 0 | I28: 0 | J28: 4 | K28: 0 | L28: 2 | M28: 720
A29: 24
A30: 25
A31: 26
A32: 27 | B32: 0 | C32: 0 | D32: =IFERROR((C32/B32),0) -> 0 | E32: 5 | F32: =H32+I32+J32+K32+L32 -> 4 | G32: =IFERROR((F32/E32),0) -> 0.8 | H32: 0 | I32: 0 | J32: 4 | K32: 0 | L32: 0 | M32: 480
A33: 28 | B33: 0 | C33: 0 | D33: =IFERROR((C33/B33),0) -> 0 | E33: 4 | F33: =H33+I33+J33+K33+L33 -> 4 | G33: =IFERROR((F33/E33),0) -> 1 | H33: 0 | I33: 0 | J33: 2 | K33: 0 | L33: 2 | M33: 300
A34: 29 | B34: 0 | C34: 0 | D34: =IFERROR((C34/B34),0) -> 0 | E34: 3 | F34: =H34+I34+J34+K34+L34 -> 3 | G34: =IFERROR((F34/E34),0) -> 1 | H34: 0 | I34: 0 | J34: 2 | K34: 0 | L34: 1 | M34: 120
A35: 30 | B35: 0 | C35: 0 | D35: =IFERROR((C35/B35),0) -> 0 | E35: 3 | F35: =H35+I35+J35+K35+L35 -> 3 | G35: =IFERROR((F35/E35),0) -> 1 | H35: 0 | I35: 0 | J35: 1 | K35: 0 | L35: 2 | M35: 570
A36: 31
A37: Total | B37: =SUM(B6:B36) -> 0 | C37: =SUM(C6:C36) -> 0 | D37: =IFERROR((C37/B37),0) -> 0 | E37: =SUM(E6:E36) -> 87 | F37: =SUM(F6:F36) -> 82 | G37: =IFERROR((F37/E37),0) -> 0.94252874 | H37: =SUM(H6:H36) -> 1 | I37: =SUM(I6:I36) -> 7 | J37: =SUM(J6:J36) -> 50 | K37: =SUM(K6:K36) -> 0 | L37: =SUM(L6:L36) -> 24 | M37: =SUM(M6:M36) -> 8200
A38: Daily Avg | B38: =B37/$B$39 -> 0 | C38: =C37/$B$39 -> 0 | D38: =IFERROR((C38/B38),0) -> 0 | E38: =E37/$B$39 -> 5.1176471 | F38: =F37/$B$39 -> 4.8235294 | G38: =IFERROR((F38/E38),0) -> 0.94252874 | H38: =H37/B39 -> 0.058823529 | I38: =I37/B39 -> 0.41176471 | J38: =J37/B39 -> 2.9411765 | K38: =K37/B39 -> 0 | L38: =L37/B39 -> 1.4117647 | M38: =M37/B39 -> 482.35294
A39: DOM | B39: =Stats!B39 -> 17

Sheet TRT
A1: Clinic:
A2: Month: | B2: =Stats!B2 -> January | C2: =Stats!C2 -> 2025
A3: New | G3: Totals | N3: Packages
A4: Day of the | B4: Sch | C4: Act | D4: Sch/Act | E4: Pt | F4: % | G4: Sch | H4: Act | I4: PV | J4: # Package | K4: Completion | L4: Wellness | M4: Wellness | N4: #1 | O4: #2 | P4: #3
A5: month | B5: D1 | C5: D1 | D5: D1 | E5: Conv | F5: Conversion | G5: PV | H5: PV | I5: % | J5: Completion | K5: Rate % | L5: Conversion | M5: Rate % | N5: 8 Pack | O5: 15 Pack | P5: 50 Pack | Q5: Total $
A6: 1
A7: 2 | B7: 0 | C7: 0 | D7: =IFERROR((C7/B7),0) -> 0 | E7: 0 | F7: =E7/C7 -> #DIV/0! | G7: 12 | H7: 11 | I7: =IFERROR((H7/G7),0) -> 0.91666667 | J7: 0 | K7: =J7/E7 -> #DIV/0! | L7: 0 | M7: =J7/L7 -> #DIV/0! | N7: 0 | O7: 0 | P7: 0 | Q7: 1262.5
A8: 3 | N8: 0.25 | Q8: 437.5
A9: 4
A10: 5
A11: 6 | B11: 2 | C11: 2 | D11: =IFERROR((C11/B11),0) -> 1 | E11: 1 | F11: =E11/C11 -> 0.5 | G11: 8 | H11: 8 | I11: =IFERROR((H11/G11),0) -> 1 | J11: 0 | K11: =J11/E11 -> 0 | L11: 0 | M11: =J11/L11 -> #DIV/0! | N11: 1 | O11: 0 | P11: 0 | Q11: 2098
A12: 7 | B12: 3 | C12: 3 | D12: =IFERROR((C12/B12),0) -> 1 | E12: 2 | F12: =E12/C12 -> 0.66666667 | G12: 7 | H12: 8 | I12: =IFERROR((H12/G12),0) -> 1.1428571 | J12: 0 | K12: =J12/E12 -> 0 | L12: 0 | M12: =J12/L12 -> #DIV/0! | N12: 2 | O12: 0 | P12: 0 | Q12: 4098
A13: 8 | B13: 0 | C13: 0 | D13: =IFERROR((C13/B13),0) -> 0 | E13: 0 | F13: =E13/C13 -> #DIV/0! | G13: 5 | H13: 5 | I13: =IFERROR((H13/G13),0) -> 1 | J13: 0 | K13: =J13/E13 -> #DIV/0! | L13: 0 | M13: =J13/L13 -> #DIV/0! | N13: 0 | O13: 0 | P13: 0 | Q13: 299
A14: 9 | B14: 1 | C14: 1 | D14: =IFERROR((C14/B14),0) -> 1 | E14: 0 | F14: =E14/C14 -> 0 | G14: 10 | H14: 11 | I14: =IFERROR((H14/G14),0) -> 1.1 | J14: 0 | K14: =J14/E14 -> #DIV/0! | L14: 0 | M14: =J14/L14 -> #DIV/0! | N14: 1.5 | O14: 0 | P14: 0 | Q14: 3549
A15: 10
A16: 11
A17: 12
A18: 13 | B18: 0 | C18: 0 | D18: =IFERROR((C18/B18),0) -> 0 | E18: 0 | F18: =E18/C18 -> #DIV/0! | G18: 8 | H18: 9 | I18: =IFERROR((H18/G18),0) -> 1.125 | J18: 0 | K18: =J18/E18 -> #DIV/0! | L18: 0 | M18: =J18/L18 -> #DIV/0! | N18: 1 | O18: 0 | P18: 0 | Q18: 2250
A19: 14 | B19: 0 | C19: 1 | D19: =IFERROR((C19/B19),0) -> 0 | E19: 0 | F19: =E19/C19 -> 0 | G19: 4 | H19: 6 | I19: =IFERROR((H19/G19),0) -> 1.5 | J19: 0 | K19: =J19/E19 -> #DIV/0! | L19: 0 | M19: =J19/L19 -> #DIV/0! | N19: 0 | O19: 0 | P19: 0 | Q19: 49
A20: 15 | B20: 1 | C20: 1 | D20: =IFERROR((C20/B20),0) -> 1 | E20: 0 | F20: =E20/C20 -> 0 | G20: 9 | H20: 9 | I20: =IFERROR((H20/G20),0) -> 1 | J20: 0 | K20: =J20/E20 -> #DIV/0! | L20: 0 | M20: =J20/L20 -> #DIV/0! | N20: 0 | O20: 0 | P20: 0 | Q20: 299
A21: 16 | B21: 0 | C21: 0 | D21: =IFERROR((C21/B21),0) -> 0 | E21: 0 | F21: =E21/C21 -> #DIV/0! | G21: 4 | H21: 5 | I21: =IFERROR((H21/G21),0) -> 1.25 | J21: 0 | K21: =J21/E21 -> #DIV/0! | L21: 0 | M21: =J21/L21 -> #DIV/0! | N21: 0 | O21: 1 | P21: 0 | Q21: 3500
A22: 17
A23: 18
A24: 19
A25: 20 | B25: 1 | C25: 1 | D25: =IFERROR((C25/B25),0) -> 1 | E25: 1 | F25: =E25/C25 -> 1 | G25: 8 | H25: 8 | I25: =IFERROR((H25/G25),0) -> 1 | J25: 0 | K25: =J25/E25 -> 0 | L25: 0 | M25: =J25/L25 -> #DIV/0! | N25: 0.5 | O25: 0 | P25: 0 | Q25: 1424
A26: 21 | B26: 1 | C26: 1 | D26: =IFERROR((C26/B26),0) -> 1 | E26: 1 | F26: =E26/C26 -> 1 | G26: 4 | H26: 5 | I26: =IFERROR((H26/G26),0) -> 1.25 | J26: 0 | K26: =J26/E26 -> 0 | L26: 0 | M26: =J26/L26 -> #DIV/0! | N26: 0.33 | O26: 0 | P26: 0 | Q26: 1583.33
A27: 22 | B27: 0 | C27: 0 | D27: =IFERROR((C27/B27),0) -> 0 | E27: 0 | F27: =E27/C27 -> #DIV/0! | G27: 7 | H27: 6 | I27: =IFERROR((H27/G27),0) -> 0.85714286 | J27: 0 | K27: =J27/E27 -> #DIV/0! | L27: 0 | M27: =J27/L27 -> #DIV/0! | N27: 0 | O27: 0 | P27: 0 | Q27: 882.34
A28: 23 | B28: 0 | C28: 0 | D28: =IFERROR((C28/B28),0) -> 0 | E28: 0 | F28: =E28/C28 -> #DIV/0! | G28: 8 | H28: 7 | I28: =IFERROR((H28/G28),0) -> 0.875 | J28: 0 | K28: =J28/E28 -> #DIV/0! | L28: 0 | M28: =J28/L28 -> #DIV/0! | N28: 0 | O28: 1 | P28: 0 | Q28: 2750
A29: 24
A30: 25
A31: 26
A32: 27 | B32: 0 | C32: 1 | D32: =IFERROR((C32/B32),0) -> 0 | E32: 1 | F32: =E32/C32 -> 1 | G32: 10 | H32: 9 | I32: =IFERROR((H32/G32),0) -> 0.9 | J32: 0 | K32: =J32/E32 -> 0 | L32: 0 | M32: =J32/L32 -> #DIV/0! | N32: 1 | O32: 0 | P32: 0 | Q32: 2049
A33: 28 | B33: 3 | C33: 3 | D33: =IFERROR((C33/B33),0) -> 1 | E33: 2 | F33: =E33/C33 -> 0.66666667 | G33: 4 | H33: 5 | I33: =IFERROR((H33/G33),0) -> 1.25 | J33: 0 | K33: =J33/E33 -> 0 | L33: 0 | M33: =J33/L33 -> #DIV/0! | N33: 1 | O33: 0 | P33: 0 | Q33: 2049
A34: 29 | B34: 0 | C34: 0 | D34: =IFERROR((C34/B34),0) -> 0 | E34: 0 | F34: =E34/C34 -> #DIV/0! | G34: 8 | H34: 9 | I34: =IFERROR((H34/G34),0) -> 1.125 | J34: 0 | K34: =J34/E34 -> #DIV/0! | L34: 0 | M34: =J34/L34 -> #DIV/0! | N34: 0 | O34: 0 | P34: 0 | Q34: 250
A35: 30 | B35: 1 | C35: 1 | D35: =IFERROR((C35/B35),0) -> 1 | E35: 1 | F35: =E35/C35 -> 1 | G35: 8 | H35: 10 | I35: =IFERROR((H35/G35),0) -> 1.25 | J35: 0 | K35: =J35/E35 -> 0 | L35: 0 | M35: =J35/L35 -> #DIV/0! | N35: 2 | O35: 0.25 | P35: 0 | Q35: 5159.5
A36: 31
A37: Total | B37: =SUM(B6:B36) -> 13 | C37: =SUM(C6:C36) -> 15 | D37: =IFERROR((C37/B37),0) -> 1.1538462 | E37: =SUM(E6:E36) -> 9 | G37: =SUM(G6:G36) -> 124 | H37: =SUM(H6:H36) -> 131 | I37: =IFERROR((H37/G37),0) -> 1.0564516 | J37: =SUM(J6:J36) -> 0 | L37: =SUM(L6:L36) -> 0 | N37: =SUM(N6:N36) -> 10.58 | O37: =SUM(O6:O36) -> 2.25 | P37: =SUM(P6:P36) -> 0 | Q37: =SUM(Q6:Q36) -> 33989.17
A38: Daily Avg | B38: =B37/$B$39 -> 0.76470588 | C38: =C37/$B$39 -> 0.88235294 | D38: =IFERROR((C38/B38),0) -> 1.1538462 | E38: =E37/B39 -> 0.52941176 | G38: =G37/$B$39 -> 7.2941176 | H38: =H37/$B$39 -> 7.7058824 | I38: =IFERROR((H38/G38),0) -> 1.0564516 | J38: =J37/B39 -> 0 | L38: =L37/B39 -> 0
A39: DOM | B39: =Stats!B39 -> 17

Sheet SDT
A1: Clinic:
A2: Month: | B2: =Stats!B2 -> January | C2: =Stats!C2 -> 2025
A3: New | G3: Totals | J3: # | N3: Packages
A4: Day of the | B4: Sch | C4: Act | D4: Sch/Act | E4: Pt | F4: % | G4: Sch | H4: Act | I4: PV | J4: Package | K4: Completion | L4: Wellness | M4: Wellness | N4: #1 | O4: #2 | P4: #3
A5: month | B5: D1 | C5: D1 | D5: D1 | E5: Conv | F5: Conversion | G5: PV | H5: PV | I5: % | J5: Completion | K5: Rate % | L5: Conversion | M5: Rate % | N5: 10 Pack | O5: 20 Pack | P5: 30 Pack | Q5: Total $
A6: 1
A7: 2 | B7: 1 | C7: 1 | D7: =IFERROR((C7/B7),0) -> 1 | E7: 1 | F7: =E7/C7 -> 1 | G7: 9 | H7: 8 | I7: =IFERROR((H7/G7),0) -> 0.88888889 | J7: 0 | K7: =J7/E7 -> 0 | L7: 0 | M7: =J7/L7 -> #DIV/0! | N7: 0 | O7: 0.25 | P7: 0 | Q7: 525
A8: 3
A9: 4
A10: 5
A11: 6 | B11: 0 | C11: 0 | D11: =IFERROR((C11/B11),0) -> 0 | E11: 0 | F11: =E11/C11 -> #DIV/0! | G11: 13 | H11: 12 | I11: =IFERROR((H11/G11),0) -> 0.92307692 | J11: 0 | K11: =J11/E11 -> #DIV/0! | L11: 0 | M11: =J11/L11 -> #DIV/0! | N11: 0 | O11: 1 | P11: 0 | Q11: 1920
A12: 7 | B12: 0 | C12: 0 | D12: =IFERROR((C12/B12),0) -> 0 | E12: 0 | F12: =E12/C12 -> #DIV/0! | G12: 3 | H12: 3 | I12: =IFERROR((H12/G12),0) -> 1 | J12: 0 | K12: =J12/E12 -> #DIV/0! | L12: 0 | M12: =J12/L12 -> #DIV/0! | N12: 0 | O12: 0 | P12: 0 | Q12: 0
A13: 8 | B13: 0 | C13: 0 | D13: =IFERROR((C13/B13),0) -> 0 | E13: 0 | F13: =E13/C13 -> #DIV/0! | G13: 5 | H13: 5 | I13: =IFERROR((H13/G13),0) -> 1 | J13: 0 | K13: =J13/E13 -> #DIV/0! | L13: 0 | M13: =J13/L13 -> #DIV/0! | N13: 0 | O13: 0 | P13: 0 | Q13: 220
A14: 9 | B14: 0 | C14: 0 | D14: =IFERROR((C14/B14),0) -> 0 | E14: 0 | F14: =E14/C14 -> #DIV/0! | G14: 13 | H14: 13 | I14: =IFERROR((H14/G14),0) -> 1 | J14: 0 | K14: =J14/E14 -> #DIV/0! | L14: 0 | M14: =J14/L14 -> #DIV/0! | N14: 0 | O14: 0 | P14: 0 | Q14: 220
A15: 10
A16: 11
A17: 12
A18: 13 | B18: 0 | C18: 0 | D18: =IFERROR((C18/B18),0) -> 0 | E18: 0 | F18: =E18/C18 -> #DIV/0! | G18: 11 | H18: 8 | I18: =IFERROR((H18/G18),0) -> 0.72727273 | J18: 0 | K18: =J18/E18 -> #DIV/0! | L18: 0 | M18: =J18/L18 -> #DIV/0! | N18: 0 | O18: 0 | P18: 0 | Q18: 110
A19: 14 | B19: 1 | C19: 1 | D19: =IFERROR((C19/B19),0) -> 1 | E19: 1 | F19: =E19/C19 -> 1 | G19: 7 | H19: 7 | I19: =IFERROR((H19/G19),0) -> 1 | J19: 0 | K19: =J19/E19 -> 0 | L19: 0 | M19: =J19/L19 -> #DIV/0! | N19: 0 | O19: 0 | P19: 0 | Q19: 220
A20: 15 | B20: 0 | C20: 0 | D20: =IFERROR((C20/B20),0) -> 0 | E20: 0 | F20: =E20/C20 -> #DIV/0! | G20: 9 | H20: 8 | I20: =IFERROR((H20/G20),0) -> 0.88888889 | J20: 0 | K20: =J20/E20 -> #DIV/0! | L20: 0 | M20: =J20/L20 -> #DIV/0! | N20: 0 | O20: 0.25 | P20: 0 | Q20: 570
A21: 16 | B21: 0 | C21: 0 | D21: =IFERROR((C21/B21),0) -> 0 | E21: 0 | F21: =E21/C21 -> #DIV/0! | G21: 9 | H21: 9 | I21: =IFERROR((H21/G21),0) -> 1 | J21: 0 | K21: =J21/E21 -> #DIV/0! | L21: 0 | M21: =J21/L21 -> #DIV/0! | N21: 0 | O21: 1 | P21: 0 | Q21: 2310
A22: 17
A23: 18
A24: 19
A25: 20 | B25: 0 | C25: 0 | D25: =IFERROR((C25/B25),0) -> 0 | E25: 0 | F25: =E25/C25 -> #DIV/0! | G25: 10 | H25: 9 | I25: =IFERROR((H25/G25),0) -> 0.9 | J25: 0 | K25: =J25/E25 -> #DIV/0! | L25: 0 | M25: =J25/L25 -> #DIV/0! | N25: 0 | O25: 0 | P25: 0 | Q25: 0
A26: 21 | B26: 0 | C26: 0 | D26: =IFERROR((C26/B26),0) -> 0 | E26: 0 | F26: =E26/C26 -> #DIV/0! | G26: 4 | H26: 4 | I26: =IFERROR((H26/G26),0) -> 1 | J26: 0 | K26: =J26/E26 -> #DIV/0! | L26: 0 | M26: =J26/L26 -> #DIV/0! | N26: 0 | O26: 0 | P26: 0 | Q26: 0
A27: 22 | B27: 0 | C27: 0 | D27: =IFERROR((C27/B27),0) -> 0 | E27: 0 | F27: =E27/C27 -> #DIV/0! | G27: 6 | H27: 7 | I27: =IFERROR((H27/G27),0) -> 1.1666667 | J27: 0 | K27: =J27/E27 -> #DIV/0! | L27: 0 | M27: =J27/L27 -> #DIV/0! | N27: 0 | O27: 1 | P27: 0 | Q27: 1320
A28: 23 | B28: 2 | C28: 2 | D28: =IFERROR((C28/B28),0) -> 1 | E28: 1 | F28: =E28/C28 -> 0.5 | G28: 8 | H28: 7 | I28: =IFERROR((H28/G28),0) -> 0.875 | J28: 0 | K28: =J28/E28 -> 0 | L28: 0 | M28: =J28/L28 -> #DIV/0! | N28: 0 | O28: 0 | P28: 0 | Q28: 110
A29: 24
A30: 25
A31: 26
A32: 27 | B32: 0 | C32: 0 | D32: =IFERROR((C32/B32),0) -> 0 | E32: 0 | F32: =E32/C32 -> #DIV/0! | G32: 9 | H32: 8 | I32: =IFERROR((H32/G32),0) -> 0.88888889 | J32: 0 | K32: =J32/E32 -> #DIV/0! | L32: 0 | M32: =J32/L32 -> #DIV/0! | N32: 0 | O32: 0.25 | P32: 0 | Q32: 460
A33: 28 | B33: 0 | C33: 0 | D33: =IFERROR((C33/B33),0) -> 0 | E33: 0 | F33: =E33/C33 -> #DIV/0! | G33: 3 | H33: 4 | I33: =IFERROR((H33/G33),0) -> 1.3333333 | J33: 0 | K33: =J33/E33 -> #DIV/0! | L33: 0 | M33: =J33/L33 -> #DIV/0! | N33: 0 | O33: 0 | P33: 0 | Q33: 0
A34: 29 | B34: 0 | C34: 0 | D34: =IFERROR((C34/B34),0) -> 0 | E34: 0 | F34: =E34/C34 -> #DIV/0! | G34: 9 | H34: 7 | I34: =IFERROR((H34/G34),0) -> 0.77777778 | J34: 0 | K34: =J34/E34 -> #DIV/0! | L34: 0 | M34: =J34/L34 -> #DIV/0! | N34: 0 | O34: 0 | P34: 0 | Q34: 696.67
A35: 30 | B35: 1 | C35: 1 | D35: =IFERROR((C35/B35),0) -> 1 | E35: 0 | F35: =E35/C35 -> 0 | G35: 12 | H35: 11 | I35: =IFERROR((H35/G35),0) -> 0.91666667 | J35: 0 | K35: =J35/E35 -> #DIV/0! | L35: 0 | M35: =J35/L35 -> #DIV/0! | N35: 0 | O35: 0 | P35: 0 | Q35: 220
A36: 31
A37: Total | B37: =SUM(B6:B36) -> 5 | C37: =SUM(C6:C36) -> 5 | D37: =IFERROR((C37/B37),0) -> 1 | G37: =SUM(G6:G36) -> 140 | H37: =SUM(H6:H36) -> 130 | I37: =IFERROR((H37/G37),0) -> 0.92857143 | J37: =SUM(J6:J36) -> 0 | L37: =SUM(L6:L36) -> 0 | N37: =SUM(N6:N36) -> 0 | O37: =SUM(O6:O36) -> 3.75 | P37: =SUM(P6:P36) -> 0 | Q37: =SUM(Q6:Q36) -> 8901.67
A38: Daily Avg | B38: =B37/$B$39 -> 0.29411765 | C38: =C37/$B$39 -> 0.29411765 | D38: =IFERROR((C38/B38),0) -> 1 | G38: =G37/$B$39 -> 8.2352941 | H38: =H37/$B$39 -> 7.6470588 | I38: =IFERROR((H38/G38),0) -> 0.92857143 | J38: =J37/B39 -> 0 | L38: =L37/B39 -> 0
A39: DOM | B39: =Stats!B39 -> 17

Sheet X-Ray
A1: Clinic:
A2: Month: | B2: =Stats!B2 -> January | C2: =Stats!C2 -> 2025
A3: New | E3: Totals
A4: Day of the | B4: Sch | C4: Act | D4: Sch/Act | E4: Sch | F4: Act | G4: PV | H4: # | N4: Full
A5: month | B5: D1 | C5: D1 | D5: D1 | E5: PV | F5: PV | G5: % | H5: Regions | I5: Cervical | J5: Thoracic | K5: Lumbar | L5: Extremity | M5: Other | N5: Spine | O5: Total $
A6: 1
A7: 2 | B7: 0 | C7: 0 | D7: =IFERROR((C7/B7),0) -> 0 | E7: 0 | F7: 0 | G7: =IFERROR((F7/E7),0) -> 0 | H7: =I7+J7+K7+L7+M7+(N7*3) -> 0 | I7: 0 | J7: 0 | K7: 0 | L7: 0 | M7: 0 | N7: 0 | O7: 0
A8: 3
A9: 4
A10: 5
A11: 6 | B11: 0 | C11: 0 | D11: =IFERROR((C11/B11),0) -> 0 | E11: 0 | F11: 0 | G11: =IFERROR((F11/E11),0) -> 0 | H11: =I11+J11+K11+L11+M11+(N11*3) -> 0 | I11: 0 | J11: 0 | K11: 0 | L11: 0 | M11: 0 | N11: 0 | O11: 0
A12: 7 | B12: 0 | C12: 0 | D12: =IFERROR((C12/B12),0) -> 0 | E12: 1 | F12: 1 | G12: =IFERROR((F12/E12),0) -> 1 | H12: =I12+J12+K12+L12+M12+(N12*3) -> 0 | I12: 0 | J12: 0 | K12: 0 | L12: 0 | M12: 0 | N12: 0 | O12: 0
A13: 8 | B13: 0 | C13: 0 | D13: =IFERROR((C13/B13),0) -> 0 | E13: 0 | F13: 0 | G13: =IFERROR((F13/E13),0) -> 0 | H13: =I13+J13+K13+L13+M13+(N13*3) -> 0 | I13: 0 | J13: 0 | K13: 0 | L13: 0 | M13: 0 | N13: 0 | O13: 75
A14: 9 | B14: 0 | C14: 0 | D14: =IFERROR((C14/B14),0) -> 0 | E14: 0 | F14: 0 | G14: =IFERROR((F14/E14),0) -> 0 | H14: =I14+J14+K14+L14+M14+(N14*3) -> 0 | I14: 0 | J14: 0 | K14: 0 | L14: 0 | M14: 0 | N14: 0 | O14: 0
A15: 10
A16: 11
A17: 12
A18: 13 | B18: 0 | C18: 0 | D18: =IFERROR((C18/B18),0) -> 0 | E18: 1 | F18: 1 | G18: =IFERROR((F18/E18),0) -> 1 | H18: =I18+J18+K18+L18+M18+(N18*3) -> 2 | I18: 1 | J18: 0 | K18: 1 | L18: 0 | M18: 0 | N18: 0 | O18: 100
A19: 14 | B19: 0 | C19: 0 | D19: =IFERROR((C19/B19),0) -> 0 | E19: 1 | F19: 1 | G19: =IFERROR((F19/E19),0) -> 1 | H19: =I19+J19+K19+L19+M19+(N19*3) -> 1 | I19: 0 | J19: 0 | K19: 1 | L19: 0 | M19: 0 | N19: 0 | O19: 50
A20: 15 | B20: 0 | C20: 0 | D20: =IFERROR((C20/B20),0) -> 0 | E20: 0 | F20: 0 | G20: =IFERROR((F20/E20),0) -> 0 | H20: =I20+J20+K20+L20+M20+(N20*3) -> 0 | I20: 0 | J20: 0 | K20: 0 | L20: 0 | M20: 0 | N20: 0 | O20: 150
A21: 16 | B21: 0 | C21: 0 | D21: =IFERROR((C21/B21),0) -> 0 | E21: 0 | F21: 0 | G21: =IFERROR((F21/E21),0) -> 0 | H21: =I21+J21+K21+L21+M21+(N21*3) -> 1 | I21: 1 | J21: 0 | K21: 0 | L21: 0 | M21: 0 | N21: 0 | O21: 50
A22: 17
A23: 18
A24: 19
A25: 20 | B25: 0 | C25: 0 | D25: =IFERROR((C25/B25),0) -> 0 | E25: 0 | F25: 0 | G25: =IFERROR((F25/E25),0) -> 0 | H25: =I25+J25+K25+L25+M25+(N25*3) -> 0 | I25: 0 | J25: 0 | K25: 0 | L25: 0 | M25: 0 | N25: 0 | O25: 0
A26: 21 | B26: 0 | C26: 0 | D26: =IFERROR((C26/B26),0) -> 0 | E26: 1 | F26: 1 | G26: =IFERROR((F26/E26),0) -> 1 | H26: =I26+J26+K26+L26+M26+(N26*3) -> 0 | I26: 0 | J26: 0 | K26: 0 | L26: 0 | M26: 0 | N26: 0 | O26: 0
A27: 22 | B27: 0 | C27: 0 | D27: =IFERROR((C27/B27),0) -> 0 | E27: 0 | F27: 0 | G27: =IFERROR((F27/E27),0) -> 0 | H27: =I27+J27+K27+L27+M27+(N27*3) -> 0 | I27: 0 | J27: 0 | K27: 0 | L27: 0 | M27: 0 | N27: 0 | O27: 0
A28: 23 | B28: 0 | C28: 0 | D28: =IFERROR((C28/B28),0) -> 0 | E28: 0 | F28: 0 | G28: =IFERROR((F28/E28),0) -> 0 | H28: =I28+J28+K28+L28+M28+(N28*3) -> 1 | I28: 1 | J28: 0 | K28: 0 | L28: 0 | M28: 0 | N28: 0 | O28: 50
A29: 24
A30: 25
A31: 26
A32: 27 | B32: 0 | C32: 0 | D32: =IFERROR((C32/B32),0) -> 0 | E32: 0 | F32: 0 | G32: =IFERROR((F32/E32),0) -> 0 | H32: =I32+J32+K32+L32+M32+(N32*3) -> 0 | I32: 0 | J32: 0 | K32: 0 | L32: 0 | M32: 0 | N32: 0 | O32: 0
A33: 28 | B33: 0 | C33: 0 | D33: =IFERROR((C33/B33),0) -> 0 | E33: 0 | F33: 0 | G33: =IFERROR((F33/E33),0) -> 0 | H33: =I33+J33+K33+L33+M33+(N33*3) -> 0 | I33: 0 | J33: 0 | K33: 0 | L33: 0 | M33: 0 | N33: 0 | O33: 0
A34: 29 | B34: 0 | C34: 0 | D34: =IFERROR((C34/B34),0) -> 0 | E34: 0 | F34: 0 | G34: =IFERROR((F34/E34),0) -> 0 | H34: =I34+J34+K34+L34+M34+(N34*3) -> 0 | I34: 0 | J34: 0 | K34: 0 | L34: 0 | M34: 0 | N34: 0 | O34: 0
A35: 30 | B35: 0 | C35: 0 | D35: =IFERROR((C35/B35),0) -> 0 | E35: 1 | F35: 1 | G35: =IFERROR((F35/E35),0) -> 1 | H35: =I35+J35+K35+L35+M35+(N35*3) -> 1 | I35: 0 | J35: 0 | K35: 1 | L35: 0 | M35: 0 | N35: 0 | O35: 50
A36: 31
A37: Total | B37: =SUM(B6:B36) -> 0 | C37: =SUM(C6:C36) -> 0 | D37: =IFERROR((C37/B37),0) -> 0 | E37: =SUM(E6:E36) -> 5 | F37: =SUM(F6:F36) -> 5 | G37: =IFERROR((F37/E37),0) -> 1 | H37: =SUM(H6:H36) -> 6 | I37: =SUM(I6:I36) -> 3 | J37: =SUM(J6:J36) -> 0 | K37: =SUM(K6:K36) -> 3 | L37: =SUM(L6:L36) -> 0 | M37: =SUM(M6:M36) -> 0 | N37: =SUM(N6:N36) -> 0 | O37: =SUM(O6:O36) -> 525
A38: Daily Avg | B38: =B37/$B$39 -> 0 | C38: =C37/$B$39 -> 0 | D38: =IFERROR((C38/B38),0) -> 0 | E38: =E37/$B$39 -> 0.29411765 | F38: =F37/$B$39 -> 0.29411765 | G38: =IFERROR((F38/E38),0) -> 1 | H38: =H37/B39 -> 0.35294118 | I38: =I37/B39 -> 0.17647059 | J38: =J37/B39 -> 0 | K38: =K37/B39 -> 0.17647059 | L38: =L37/B39 -> 0 | M38: =M37/B39 -> 0 | N38: =N37/B39 -> 0 | O38: =O37/B39 -> 30.882353
A39: DOM | B39: =Stats!B39 -> 17

Sheet SHP
A1: Clinic:
A2: Month: | B2: =Stats!B2 -> January | C2: =Stats!C2 -> 2025
A3: New | G3: Totals
A4: Day of the | B4: Sch | C4: Act | D4: Sch/Act | E4: Pt | F4: % | G4: Sch | H4: Act | I4: PV | J4: Opt Out
A5: month | B5: D1 | C5: D1 | D5: D1 | E5: Conv | F5: Conversion | G5: PV | H5: PV | I5: % | J5: Rate | K5: Total $
A6: 1
A7: 2 | B7: 0 | C7: 0 | D7: =IFERROR((C7/B7),0) -> 0 | E7: 0 | F7: =E7/C7 -> #DIV/0! | G7: 2 | H7: 1 | I7: =IFERROR((H7/G7),0) -> 0.5 | J7: 0 | K7: 0
A8: 3
A9: 4
A10: 5
A11: 6 | B11: 0 | C11: 0 | D11: =IFERROR((C11/B11),0) -> 0 | E11: 0 | F11: =E11/C11 -> #DIV/0! | G11: 2 | H11: 2 | I11: =IFERROR((H11/G11),0) -> 1 | J11: 0 | K11: 0
A12: 7 | B12: 0 | C12: 0 | D12: =IFERROR((C12/B12),0) -> 0 | E12: 0 | F12: =E12/C12 -> #DIV/0! | G12: 0 | H12: 0 | I12: =IFERROR((H12/G12),0) -> 0 | J12: 0 | K12: 0
A13: 8 | B13: 0 | C13: 0 | D13: =IFERROR((C13/B13),0) -> 0 | E13: 0 | F13: =E13/C13 -> #DIV/0! | G13: 2 | H13: 2 | I13: =IFERROR((H13/G13),0) -> 1 | J13: 0 | K13: 0
A14: 9 | B14: 0 | C14: 0 | D14: =IFERROR((C14/B14),0) -> 0 | E14: 0 | F14: =E14/C14 -> #DIV/0! | G14: 2 | H14: 2 | I14: =IFERROR((H14/G14),0) -> 1 | J14: 0 | K14: 0
A15: 10
A16: 11
A17: 12
A18: 13 | B18: 0 | C18: 0 | D18: =IFERROR((C18/B18),0) -> 0 | E18: 0 | F18: =E18/C18 -> #DIV/0! | G18: 2 | H18: 3 | I18: =IFERROR((H18/G18),0) -> 1.5 | J18: 0 | K18: 0
A19: 14 | B19: 0 | C19: 0 | D19: =IFERROR((C19/B19),0) -> 0 | E19: 0 | F19: =E19/C19 -> #DIV/0! | G19: 1 | H19: 1 | I19: =IFERROR((H19/G19),0) -> 1 | J19: 0 | K19: 0
A20: 15 | B20: 0 | C20: 0 | D20: =IFERROR((C20/B20),0) -> 0 | E20: 0 | F20: =E20/C20 -> #DIV/0! | G20: 2 | H20: 1 | I20: =IFERROR((H20/G20),0) -> 0.5 | J20: 0 | K20: 0
A21: 16 | B21: 0 | C21: 0 | D21: =IFERROR((C21/B21),0) -> 0 | E21: 0 | F21: =E21/C21 -> #DIV/0! | G21: 1 | H21: 0 | I21: =IFERROR((H21/G21),0) -> 0 | J21: 0 | K21: 0
A22: 17
A23: 18
A24: 19 | K24: 599
A25: 20 | B25: 0 | C25: 0 | D25: =IFERROR((C25/B25),0) -> 0 | E25: 0 | F25: =E25/C25 -> #DIV/0! | G25: 2 | H25: 1 | I25: =IFERROR((H25/G25),0) -> 0.5 | J25: 0 | K25: 0
A26: 21 | B26: 0 | C26: 0 | D26: =IFERROR((C26/B26),0) -> 0 | E26: 0 | F26: =E26/C26 -> #DIV/0! | G26: 1 | H26: 1 | I26: =IFERROR((H26/G26),0) -> 1 | J26: 0 | K26: 0
A27: 22 | B27: 0 | C27: 0 | D27: =IFERROR((C27/B27),0) -> 0 | E27: 0 | F27: =E27/C27 -> #DIV/0! | G27: 0 | H27: 0 | I27: =IFERROR((H27/G27),0) -> 0 | J27: 0 | K27: 599
A28: 23 | B28: 0 | C28: 0 | D28: =IFERROR((C28/B28),0) -> 0 | E28: 0 | F28: =E28/C28 -> #DIV/0! | G28: 1 | H28: 1 | I28: =IFERROR((H28/G28),0) -> 1 | J28: 0 | K28: 0
A29: 24
A30: 25
A31: 26
A32: 27 | B32: 0 | C32: 0 | D32: =IFERROR((C32/B32),0) -> 0 | E32: 0 | F32: =E32/C32 -> #DIV/0! | G32: 1 | H32: 1 | I32: =IFERROR((H32/G32),0) -> 1 | J32: 0 | K32: 0
A33: 28 | B33: 0 | C33: 0 | D33: =IFERROR((C33/B33),0) -> 0 | E33: 0 | F33: =E33/C33 -> #DIV/0! | G33: 1 | H33: 1 | I33: =IFERROR((H33/G33),0) -> 1 | J33: 0 | K33: 0
A34: 29 | B34: 0 | C34: 0 | D34: =IFERROR((C34/B34),0) -> 0 | E34: 0 | F34: =E34/C34 -> #DIV/0! | G34: 1 | H34: 0 | I34: =IFERROR((H34/G34),0) -> 0 | J34: 0 | K34: 0
A35: 30 | B35: 0 | C35: 0 | D35: =IFERROR((C35/B35),0) -> 0 | E35: 0 | F35: =E35/C35 -> #DIV/0! | G35: 2 | H35: 1 | I35: =IFERROR((H35/G35),0) -> 0.5 | J35: 0 | K35: 0
A36: 31
A37: Total | B37: =SUM(B6:B36) -> 0 | C37: =SUM(C6:C36) -> 0 | D37: =IFERROR((C37/B37),0) -> 0 | E37: =SUM(E6:E36) -> 0 | G37: =SUM(G6:G36) -> 23 | H37: =SUM(H6:H36) -> 18 | I37: =IFERROR((H37/G37),0) -> 0.7826087 | J37: =SUM(J6:J36) -> 0 | K37: =SUM(K6:K36) -> 1198
A38: Daily Avg | B38: =B37/$B$39 -> 0 | C38: =C37/$B$39 -> 0 | D38: =IFERROR((C38/B38),0) -> 0 | E38: =E37/B39 -> 0 | G38: =G37/$B$39 -> 1.3529412 | H38: =H37/$B$39 -> 1.0588235 | I38: =IFERROR((H38/G38),0) -> 0.7826087 | J38: =J37/B39 -> 0 | K38: =K37/B39 -> 70.470588
A39: DOM | B39: =Stats!B39 -> 17

Sheet EWOT
A1: Clinic:
A2: Month: | B2: =Stats!B2 -> January | C2: =Stats!C2 -> 2025
A3: New | G3: Totals
A4: Day of the | B4: Sch | C4: Act | D4: Sch/Act | E4: Pt | F4: % | G4: Sch | H4: Act | I4: PV | J4: Opt Out
A5: month | B5: D1 | C5: D1 | D5: D1 | E5: Conv | F5: Conversion | G5: PV | H5: PV | I5: % | J5: Rate | K5: Total $
A6: 1
A7: 2 | B7: 0 | C7: 0 | D7: =IFERROR((C7/B7),0) -> 0 | E7: 0 | F7: =E7/C7 -> #DIV/0! | G7: 0 | H7: 0 | I7: =IFERROR((H7/G7),0) -> 0 | J7: 0 | K7: 0
A8: 3
A9: 4
A10: 5
A11: 6 | B11: 0 | C11: 0 | D11: =IFERROR((C11/B11),0) -> 0 | E11: 0 | F11: =E11/C11 -> #DIV/0! | G11: 0 | H11: 0 | I11: =IFERROR((H11/G11),0) -> 0 | J11: 0 | K11: 0
A12: 7 | B12: 0 | C12: 0 | D12: =IFERROR((C12/B12),0) -> 0 | E12: 0 | F12: =E12/C12 -> #DIV/0! | G12: 0 | H12: 0 | I12: =IFERROR((H12/G12),0) -> 0 | J12: 0 | K12: 0
A13: 8 | B13: 0 | C13: 0 | D13: =IFERROR((C13/B13),0) -> 0 | E13: 0 | F13: =E13/C13 -> #DIV/0! | G13: 0 | H13: 0 | I13: =IFERROR((H13/G13),0) -> 0 | J13: 0 | K13: 0
A14: 9 | B14: 0 | C14: 0 | D14: =IFERROR((C14/B14),0) -> 0 | E14: 0 | F14: =E14/C14 -> #DIV/0! | G14: 0 | H14: 0 | I14: =IFERROR((H14/G14),0) -> 0 | J14: 0 | K14: 0
A15: 10
A16: 11
A17: 12
A18: 13 | B18: 0 | C18: 0 | D18: =IFERROR((C18/B18),0) -> 0 | E18: 0 | F18: =E18/C18 -> #DIV/0! | G18: 0 | H18: 0 | I18: =IFERROR((H18/G18),0) -> 0 | J18: 0 | K18: 0
A19: 14 | B19: 0 | C19: 0 | D19: =IFERROR((C19/B19),0) -> 0 | E19: 0 | F19: =E19/C19 -> #DIV/0! | G19: 0 | H19: 0 | I19: =IFERROR((H19/G19),0) -> 0 | J19: 0 | K19: 0
A20: 15 | B20: 0 | C20: 0 | D20: =IFERROR((C20/B20),0) -> 0 | E20: 0 | F20: =E20/C20 -> #DIV/0! | G20: 0 | H20: 0 | I20: =IFERROR((H20/G20),0) -> 0 | J20: 0 | K20: 0
A21: 16 | B21: 0 | C21: 0 | D21: =IFERROR((C21/B21),0) -> 0 | E21: 0 | F21: =E21/C21 -> #DIV/0! | G21: 0 | H21: 0 | I21: =IFERROR((H21/G21),0) -> 0 | J21: 0 | K21: 0
A22: 17
A23: 18
A24: 19
A25: 20 | B25: 0 | C25: 0 | D25: =IFERROR((C25/B25),0) -> 0 | E25: 0 | F25: =E25/C25 -> #DIV/0! | G25: 0 | H25: 0 | I25: =IFERROR((H25/G25),0) -> 0 | J25: 0 | K25: 0
A26: 21 | B26: 0 | C26: 0 | D26: =IFERROR((C26/B26),0) -> 0 | E26: 0 | F26: =E26/C26 -> #DIV/0! | G26: 0 | H26: 0 | I26: =IFERROR((H26/G26),0) -> 0 | J26: 0 | K26: 0
A27: 22 | B27: 0 | C27: 0 | D27: =IFERROR((C27/B27),0) -> 0 | E27: 0 | F27: =E27/C27 -> #DIV/0! | G27: 0 | H27: 0 | I27: =IFERROR((H27/G27),0) -> 0 | J27: 0 | K27: 0
A28: 23 | B28: 0 | C28: 0 | D28: =IFERROR((C28/B28),0) -> 0 | E28: 0 | F28: =E28/C28 -> #DIV/0! | G28: 0 | H28: 0 | I28: =IFERROR((H28/G28),0) -> 0 | J28: 0 | K28: 0
A29: 24
A30: 25
A31: 26
A32: 27 | B32: 0 | C32: 0 | D32: =IFERROR((C32/B32),0) -> 0 | E32: 0 | F32: =E32/C32 -> #DIV/0! | G32: 0 | H32: 0 | I32: =IFERROR((H32/G32),0) -> 0 | J32: 0 | K32: 0
A33: 28 | B33: 0 | C33: 0 | D33: =IFERROR((C33/B33),0) -> 0 | E33: 0 | F33: =E33/C33 -> #DIV/0! | G33: 0 | H33: 0 | I33: =IFERROR((H33/G33),0) -> 0 | J33: 0 | K33: 0
A34: 29 | B34: 0 | C34: 0 | D34: =IFERROR((C34/B34),0) -> 0 | E34: 0 | F34: =E34/C34 -> #DIV/0! | G34: 0 | H34: 0 | I34: =IFERROR((H34/G34),0) -> 0 | J34: 0 | K34: 0
A35: 30 | B35: 0 | C35: 0 | D35: =IFERROR((C35/B35),0) -> 0 | E35: 0 | F35: =E35/C35 -> #DIV/0! | G35: 0 | H35: 0 | I35: =IFERROR((H35/G35),0) -> 0 | J35: 0 | K35: 0
A36: 31
A37: Total | B37: =SUM(B6:B36) -> 0 | C37: =SUM(C6:C36) -> 0 | D37: =IFERROR((C37/B37),0) -> 0 | E37: =SUM(E6:E36) -> 0 | G37: =SUM(G6:G36) -> 0 | H37: =SUM(H6:H36) -> 0 | I37: =IFERROR((H37/G37),0) -> 0 | J37: =SUM(J6:J36) -> 0 | K37: =SUM(K6:K36) -> 0
A38: Daily Avg | B38: =B37/$B$39 -> 0 | C38: =C37/$B$39 -> 0 | D38: =IFERROR((C38/B38),0) -> 0 | E38: =E37/B39 -> 0 | G38: =G37/$B$39 -> 0 | H38: =H37/$B$39 -> 0 | I38: =IFERROR((H38/G38),0) -> 0 | J38: =J37/B39 -> 0 | K38: =K37/B39 -> 0
A39: DOM | B39: =Stats!B39 -> 17

Sheet PEMF
A1: Clinic:
A2: Month: | B2: =Stats!B2 -> January | C2: =Stats!C2 -> 2025
A3: New | G3: Totals
A4: Day of the | B4: Sch | C4: Act | D4: Sch/Act | E4: Pt | F4: % | G4: Sch | H4: Act | I4: PV | J4: Opt Out
A5: month | B5: D1 | C5: D1 | D5: D1 | E5: Conv | F5: Conversion | G5: PV | H5: PV | I5: % | J5: Rate | K5: Total $
A6: 1
A7: 2 | B7: 0 | C7: 0 | D7: =IFERROR((C7/B7),0) -> 0 | E7: 0 | F7: =E7/C7 -> #DIV/0! | G7: 0 | H7: 0 | I7: =IFERROR((H7/G7),0) -> 0 | J7: 0 | K7: 0
A8: 3
A9: 4
A10: 5
A11: 6 | B11: 0 | C11: 0 | D11: =IFERROR((C11/B11),0) -> 0 | E11: 0 | F11: =E11/C11 -> #DIV/0! | G11: 0 | H11: 0 | I11: =IFERROR((H11/G11),0) -> 0 | J11: 0 | K11: 0
A12: 7 | B12: 0 | C12: 0 | D12: =IFERROR((C12/B12),0) -> 0 | E12: 0 | F12: =E12/C12 -> #DIV/0! | G12: 0 | H12: 0 | I12: =IFERROR((H12/G12),0) -> 0 | J12: 0 | K12: 0
A13: 8 | B13: 0 | C13: 0 | D13: =IFERROR((C13/B13),0) -> 0 | E13: 0 | F13: =E13/C13 -> #DIV/0! | G13: 0 | H13: 0 | I13: =IFERROR((H13/G13),0) -> 0 | J13: 0 | K13: 0
A14: 9 | B14: 0 | C14: 0 | D14: =IFERROR((C14/B14),0) -> 0 | E14: 0 | F14: =E14/C14 -> #DIV/0! | G14: 0 | H14: 0 | I14: =IFERROR((H14/G14),0) -> 0 | J14: 0 | K14: 0
A15: 10
A16: 11
A17: 12
A18: 13 | B18: 0 | C18: 0 | D18: =IFERROR((C18/B18),0) -> 0 | E18: 0 | F18: =E18/C18 -> #DIV/0! | G18: 0 | H18: 0 | I18: =IFERROR((H18/G18),0) -> 0 | J18: 0 | K18: 0
A19: 14 | B19: 0 | C19: 0 | D19: =IFERROR((C19/B19),0) -> 0 | E19: 0 | F19: =E19/C19 -> #DIV/0! | G19: 0 | H19: 0 | I19: =IFERROR((H19/G19),0) -> 0 | J19: 0 | K19: 0
A20: 15 | B20: 0 | C20: 0 | D20: =IFERROR((C20/B20),0) -> 0 | E20: 0 | F20: =E20/C20 -> #DIV/0! | G20: 0 | H20: 0 | I20: =IFERROR((H20/G20),0) -> 0 | J20: 0 | K20: 0
A21: 16 | B21: 0 | C21: 0 | D21: =IFERROR((C21/B21),0) -> 0 | E21: 0 | F21: =E21/C21 -> #DIV/0! | G21: 0 | H21: 0 | I21: =IFERROR((H21/G21),0) -> 0 | J21: 0 | K21: 0
A22: 17
A23: 18
A24: 19
A25: 20 | B25: 0 | C25: 0 | D25: =IFERROR((C25/B25),0) -> 0 | E25: 0 | F25: =E25/C25 -> #DIV/0! | G25: 0 | H25: 0 | I25: =IFERROR((H25/G25),0) -> 0 | J25: 0 | K25: 0
